Workbook

Sheet 算分
A1: 广西玉柴机器股份有限公司 Guangxi Yuchai Machinery Co.,Ltd.
A2: 记录编号：QM/YCF13-70-06-870 | F2: 潜在失效模式及后果分析
A3: 公司名: | D3: 广西玉柴机器股份有限公司 | L3: 产品系列代号: | O3: K11 | W3: 项目: | X3: 2023K11DSKQG6010/K11国六高效版起重机 | AE3: - | AF3: DFMEA | AG3: 01 | AK3: DFMEA编号： | AL3: =O6&AE3&AF3&AG3 -> K11-1004040-02SF9-DFMEA01
A4: 工厂地址: | D4: 广西玉林市天桥西路88号 | L4: 子系统名称： | O4: 热动子系统 | W4: DFMEA开始日期: | X4: 45420 | AK4: 设计负责人： | AL4: 韦良锦
A5: 客户名: | D5: 东风柳州汽车有限公司 | L5: 零件名称： | O5: 活塞环组件 | W5: DFMEA 修订日期: | X5: / | AK5: 保密等级： | AL5: 秘密
A6: 车型/ 年 / 平台 | D6: 起重机/2023/K | L6: 零件代号： | O6: K11-1004040-02SF9 | W6: 跨职能团队： | X6: 何哲易（设计）、韦良锦（设计）、周磊磊（系统）、张锦（设计）、伍平铅（测试）
A7: 背景介绍： | D7: K11-1004040-02SF8基础上改一环梯角和三环弹力
A8: 结构分析 | G8: 功能分析 | P8: 失效分析 | X8: 风险分析 | AF8: 优化
A9: 1.上一高层级名称 | C9: 2.聚焦要素名称 | E9: 3.下一较低级别或特性类型 | G9: 1.上一高层级功能及要求 | J9: 2. 关注要素功能及要求 | M9: 3.下一低层级的功能及要求或特性 | P9: 1.对于上一高层级要素或最终用户的失效影响(FE) | S9: 严重度S | T9: 2.关注要素的失效模式(FM) | V9: 3. 下一低层级要素或特性的失效原因(FC) | X9: FC的当前预防控制 (PC) | Z9: FC的频度(O) | AA9: FC或FM的当前探测控制 (DC) | AC9: FCFM探测度(D) | AD9: AP | AE9: 过滤码 (可选) | AF9: 预防措施 | AH9: 探测措施 | AJ9: 责任人 | AK9: 目标完成时间 | AL9: 状态: [原样, 考虑中, 进行中, 完成, 取消] | AN9: 采取行动的证据 | AO9: 完成日期 | AP9: 严重度 (S) | AQ9: 频度 (O) | AR9: 探测度(D) | AS9: AP | AT9: 过滤码 (可选)
A13: 曲柄连杆模块 | C13: 活塞环组件 | E13: 环体 | G13: 将活塞往复 运动转化为 旋转运动 | J13: 1、控制气缸壁油膜厚度 2、密封高压气体进入曲轴箱 3、传递活塞环区热量给气缸套 4、给活塞支撑导向作用 | M13: 从活塞传递热量给气缸套；支撑活塞 | P13: 拉缸 | S13: 7 | T13: 断裂 | V13: 材料选择不当 | X13: 活塞燃烧室的尺寸、形状轮廓不符合输入要求，容积不满足47.25±0.8mL要求 | Y13: 活塞燃烧室的尺寸、形状轮廓不符合输入要求，容积不满足47.25±0.8mL要求 | Z13: 2 | AA13: 设计三维测量校准燃烧室容积满足47.25±0.8mL | AB13: 设计三维测量校准燃烧室容积满足47.25±0.8mL | AC13: 2 | AD13: L | AH13: 1 | AI13: 1
A14: 曲柄连杆模块 | C14: 活塞环组件 | E14: 活塞环上下表面 | G14: 将活塞往复 运动转化为 旋转运动 | J14: 1、控制气缸壁油膜厚度 2、密封高压气体进入曲轴箱 3、传递活塞环区热量给气缸套 4、给活塞支撑导向作用 | M14: 与活塞环槽表面贴合；承载环区空间气压 | P14: 拉缸 | S14: 7 | T14: 卡环 | V14: 开口间隙：一环＜0.25；二环＜0.6，三环＜0.25 侧隙:一环＜0.07；二环＜0.07，三环＜0.035 | X14: 活塞结构设计安全系数＜1.2 | Y14: 活塞结构设计安全系数＜1.2 | Z14: 2 | AA14: 1、设计阶段活塞CAE结构强度分析安全系数≥1.2 2、活塞单体疲劳试验 | AB14: 1、设计阶段活塞CAE结构强度分析安全系数≥1.2 2、活塞单体疲劳试验 | AC14: 4 | AD14: =IF(S14=1,"L",IF(AND(1<S14,S14<=3),INDEX(AP!$B$41:$L$51,MATCH(算分!Z14,AP!$B$41:$B$51,1),MATCH(算分!AC14,AP!$B$41:$L$41,1)),IF(AND(3<S14,S14<=6),INDEX(AP!$B$28:$L$38,MATCH(算分!Z14,AP!$B$28:$B$38,1),MATCH(算分!AC14,AP!$B$28:$L$28,1)),IF(AND(6<S14,S14<=8),INDEX(AP!$B$15:$L$25,MATCH(算分!Z14,AP!$B$15:$B$25,1),MATCH(算分!AC14,AP!$B$15:$L$15,1)),IF(AND(8<S14,S14<=10),INDEX(AP!$B$2:$L$12,MATCH(算分!Z14,AP!$B$2:$B$12,1),MATCH(算分!AC14,AP!$B$2:$L$2,1)),""))))) -> L | AF14: 高分 | AH14: 2 | AI14: 2
A15: 曲柄连杆模块 | C15: 活塞环组件 | E15: 活塞环上下表面 | G15: 将活塞往复 运动转化为 旋转运动 | J15: 1、控制气缸壁油膜厚度 2、密封高压气体进入曲轴箱 3、传递活塞环区热量给气缸套 4、给活塞支撑导向作用 | M15: 与活塞环槽表面贴合；承载环区空间气压 | P15: 机油耗高 | S15: 7 | T15: 窜机油 | V15: 侧隙mm：一环＞0.12；二环＞0.11，三环＞0.075 表面粗糙度＞Rz4 | X15: 活塞外径大于109.89±0.009，导致拉缸 | Y15: 活塞外径大于109.89±0.009，导致拉缸 | Z15: 2 | AA15: 活塞外径满足109.89±0.009 | AB15: 活塞外径满足109.89±0.009 | AC15: 4 | AD15: =IF(S15=1,"L",IF(AND(1<S15,S15<=3),INDEX(AP!$B$41:$L$51,MATCH(算分!Z15,AP!$B$41:$B$51,1),MATCH(算分!AC15,AP!$B$41:$L$41,1)),IF(AND(3<S15,S15<=6),INDEX(AP!$B$28:$L$38,MATCH(算分!Z15,AP!$B$28:$B$38,1),MATCH(算分!AC15,AP!$B$28:$L$28,1)),IF(AND(6<S15,S15<=8),INDEX(AP!$B$15:$L$25,MATCH(算分!Z15,AP!$B$15:$B$25,1),MATCH(算分!AC15,AP!$B$15:$L$15,1)),IF(AND(8<S15,S15<=10),INDEX(AP!$B$2:$L$12,MATCH(算分!Z15,AP!$B$2:$B$12,1),MATCH(算分!AC15,AP!$B$2:$L$2,1)),""))))) -> L | AH15: 3 | AI15: 3
A16: 曲柄连杆模块 | C16: 活塞环组件 | E16: 活塞环上下表面 | G16: 将活塞往复 运动转化为 旋转运动 | J16: 1、控制气缸壁油膜厚度 2、密封高压气体进入曲轴箱 3、传递活塞环区热量给气缸套 4、给活塞支撑导向作用 | M16: 与活塞环槽表面贴合；承载环区空间气压 | P16: 机油耗高 | S16: 7 | T16: 窜机油 | V16: 怠速时缸内＜-30Kpa | X16: 1、活塞环组件与活塞轴向间隙控制不满足要求mm：气环：0.12±0.02、刮油环：0.08±0.02、油环部件：0.05±0.02；导致卡环 | Y16: 1、活塞环组件与活塞轴向间隙控制不满足要求mm：气环：0.12±0.02、刮油环：0.08±0.02、油环部件：0.05±0.02；导致卡环 | Z16: 2 | AA16: 1、活塞环组件与活塞轴向间隙控制mm：气环：0.12±0.02、刮油环：0.08±0.02、油环部件：0.05±0.02 | AB16: 1、活塞环组件与活塞轴向间隙控制mm：气环：0.12±0.02、刮油环：0.08±0.02、油环部件：0.05±0.02 | AC16: 4 | AD16: =IF(S16=1,"L",IF(AND(1<S16,S16<=3),INDEX(AP!$B$41:$L$51,MATCH(算分!Z16,AP!$B$41:$B$51,1),MATCH(算分!AC16,AP!$B$41:$L$41,1)),IF(AND(3<S16,S16<=6),INDEX(AP!$B$28:$L$38,MATCH(算分!Z16,AP!$B$28:$B$38,1),MATCH(算分!AC16,AP!$B$28:$L$28,1)),IF(AND(6<S16,S16<=8),INDEX(AP!$B$15:$L$25,MATCH(算分!Z16,AP!$B$15:$B$25,1),MATCH(算分!AC16,AP!$B$15:$L$15,1)),IF(AND(8<S16,S16<=10),INDEX(AP!$B$2:$L$12,MATCH(算分!Z16,AP!$B$2:$B$12,1),MATCH(算分!AC16,AP!$B$2:$L$2,1)),""))))) -> L | AF16: 高分 | AH16: 4 | AI16: 4
A17: 曲柄连杆模块 | C17: 活塞环组件 | E17: 活塞环上下表面 | G17: 将活塞往复 运动转化为 旋转运动 | J17: 1、控制气缸壁油膜厚度 2、密封高压气体进入曲轴箱 3、传递活塞环区热量给气缸套 4、给活塞支撑导向作用 | M17: 与活塞环槽表面贴合；承载环区空间气压 | P17: 机油耗高 | S17: 7 | T17: 窜机油 | V17: 环内侧边缘有毛刺 | X17: 活塞清洁度＞24mg，清洁度控制问题导致拉缸 | Y17: 活塞清洁度＞24mg，清洁度控制问题导致拉缸 | Z17: 1 | AA17: 图纸按Q/YC 11 清洁度要求执行 | AB17: 图纸按Q/YC 11 清洁度要求执行 | AC17: 5 | AD17: =IF(S17=1,"L",IF(AND(1<S17,S17<=3),INDEX(AP!$B$41:$L$51,MATCH(算分!Z17,AP!$B$41:$B$51,1),MATCH(算分!AC17,AP!$B$41:$L$41,1)),IF(AND(3<S17,S17<=6),INDEX(AP!$B$28:$L$38,MATCH(算分!Z17,AP!$B$28:$B$38,1),MATCH(算分!AC17,AP!$B$28:$L$28,1)),IF(AND(6<S17,S17<=8),INDEX(AP!$B$15:$L$25,MATCH(算分!Z17,AP!$B$15:$B$25,1),MATCH(算分!AC17,AP!$B$15:$L$15,1)),IF(AND(8<S17,S17<=10),INDEX(AP!$B$2:$L$12,MATCH(算分!Z17,AP!$B$2:$B$12,1),MATCH(算分!AC17,AP!$B$2:$L$2,1)),""))))) -> L | AH17: 5 | AI17: 5
A18: 曲柄连杆模块 | C18: 活塞环组件 | E18: 活塞环外表面 | G18: 将活塞往复 运动转化为 旋转运动 | J18: 1、控制气缸壁油膜厚度 2、密封高压气体进入曲轴箱 3、传递活塞环区热量给气缸套 4、给活塞支撑导向作用 | M18: 与缸套表面、活塞环槽表面贴合 | P18: 机油耗高 | S18: 7 | T18: 磨损 | V18: 面压不足：MPa 一环：＜0.16～0.21 二环：＜0.13～0.19 油环：＜1.33～1.75 | X18: 活塞销孔直径＜46.007，导致活塞销和销孔卡死 | Y18: 活塞销孔直径＜46.007，导致活塞销和销孔卡死 | Z18: 2 | AA18: 按Q/YC 2511《曲柄连杆系统开发规范》控制间隙 | AB18: 按Q/YC 2511《曲柄连杆系统开发规范》控制间隙 | AC18: 4 | AD18: =IF(S18=1,"L",IF(AND(1<S18,S18<=3),INDEX(AP!$B$41:$L$51,MATCH(算分!Z18,AP!$B$41:$B$51,1),MATCH(算分!AC18,AP!$B$41:$L$41,1)),IF(AND(3<S18,S18<=6),INDEX(AP!$B$28:$L$38,MATCH(算分!Z18,AP!$B$28:$B$38,1),MATCH(算分!AC18,AP!$B$28:$L$28,1)),IF(AND(6<S18,S18<=8),INDEX(AP!$B$15:$L$25,MATCH(算分!Z18,AP!$B$15:$B$25,1),MATCH(算分!AC18,AP!$B$15:$L$15,1)),IF(AND(8<S18,S18<=10),INDEX(AP!$B$2:$L$12,MATCH(算分!Z18,AP!$B$2:$B$12,1),MATCH(算分!AC18,AP!$B$2:$L$2,1)),""))))) -> L | AF18: 高分 | AH18: 6 | AI18: 6
A19: 曲柄连杆模块 | C19: 活塞环组件 | E19: 活塞环外表面 | G19: 将活塞往复 运动转化为 旋转运动 | J19: 1、控制气缸壁油膜厚度 2、密封高压气体进入曲轴箱 3、传递活塞环区热量给气缸套 4、给活塞支撑导向作用 | M19: 与缸套表面、活塞环槽表面贴合 | P19: 机油耗高 | S19: 7 | T19: 磨损 | V19: 涂层耐磨性不足 | X19: 活塞销安全系数＜1.2，导致活塞销断裂 | Y19: 活塞销安全系数＜1.2，导致活塞销断裂 | Z19: 1 | AA19: 设计阶段活塞销CAE结构强度分析安全系数≥1.2 | AB19: 设计阶段活塞销CAE结构强度分析安全系数≥1.2 | AC19: 6 | AD19: =IF(S19=1,"L",IF(AND(1<S19,S19<=3),INDEX(AP!$B$41:$L$51,MATCH(算分!Z19,AP!$B$41:$B$51,1),MATCH(算分!AC19,AP!$B$41:$L$41,1)),IF(AND(3<S19,S19<=6),INDEX(AP!$B$28:$L$38,MATCH(算分!Z19,AP!$B$28:$B$38,1),MATCH(算分!AC19,AP!$B$28:$L$28,1)),IF(AND(6<S19,S19<=8),INDEX(AP!$B$15:$L$25,MATCH(算分!Z19,AP!$B$15:$B$25,1),MATCH(算分!AC19,AP!$B$15:$L$15,1)),IF(AND(8<S19,S19<=10),INDEX(AP!$B$2:$L$12,MATCH(算分!Z19,AP!$B$2:$B$12,1),MATCH(算分!AC19,AP!$B$2:$L$2,1)),""))))) -> L | AF19: 高分 | AH19: 7 | AI19: 7
A20: 曲柄连杆模块 | C20: 活塞环组件 | E20: 开口处 | G20: 将活塞往复 运动转化为 旋转运动 | J20: 1、控制气缸壁油膜厚度 2、密封高压气体进入曲轴箱 3、传递活塞环区热量给气缸套 4、给活塞支撑导向作用 | M20: 防止环受热膨胀顶死 | P20: 拉缸 | S20: 7 | T20: 磨损 | V20: 开口间隙：一环＜0.25；二环＜0.6，三环＜0.25 侧隙:一环＜0.07；二环＜0.07，三环＜0.035 | X20: 活塞清洁度＞24mg，导致活塞销拉伤抱死 | Y20: 活塞清洁度＞24mg，导致活塞销拉伤抱死 | Z20: 1 | AA20: 图纸按Q/YC 11 清洁度要求执行 | AB20: 图纸按Q/YC 11 清洁度要求执行 | AC20: 5 | AD20: =IF(S20=1,"L",IF(AND(1<S20,S20<=3),INDEX(AP!$B$41:$L$51,MATCH(算分!Z20,AP!$B$41:$B$51,1),MATCH(算分!AC20,AP!$B$41:$L$41,1)),IF(AND(3<S20,S20<=6),INDEX(AP!$B$28:$L$38,MATCH(算分!Z20,AP!$B$28:$B$38,1),MATCH(算分!AC20,AP!$B$28:$L$28,1)),IF(AND(6<S20,S20<=8),INDEX(AP!$B$15:$L$25,MATCH(算分!Z20,AP!$B$15:$B$25,1),MATCH(算分!AC20,AP!$B$15:$L$15,1)),IF(AND(8<S20,S20<=10),INDEX(AP!$B$2:$L$12,MATCH(算分!Z20,AP!$B$2:$B$12,1),MATCH(算分!AC20,AP!$B$2:$L$2,1)),""))))) -> L | AH20: 8 | AI20: 8
S21: 7 | X21: 连杆部件整体安全系数小于1.2，导致连杆断裂 | Y21: 连杆部件整体安全系数小于1.2，导致连杆断裂 | Z21: 3 | AA21: 设计阶段连杆部件CAE结构强度分析安全系数≥1.2 | AB21: 设计阶段连杆部件CAE结构强度分析安全系数≥1.2 | AC21: 4 | AD21: =IF(S21=1,"L",IF(AND(1<S21,S21<=3),INDEX(AP!$B$41:$L$51,MATCH(算分!Z21,AP!$B$41:$B$51,1),MATCH(算分!AC21,AP!$B$41:$L$41,1)),IF(AND(3<S21,S21<=6),INDEX(AP!$B$28:$L$38,MATCH(算分!Z21,AP!$B$28:$B$38,1),MATCH(算分!AC21,AP!$B$28:$L$28,1)),IF(AND(6<S21,S21<=8),INDEX(AP!$B$15:$L$25,MATCH(算分!Z21,AP!$B$15:$B$25,1),MATCH(算分!AC21,AP!$B$15:$L$15,1)),IF(AND(8<S21,S21<=10),INDEX(AP!$B$2:$L$12,MATCH(算分!Z21,AP!$B$2:$B$12,1),MATCH(算分!AC21,AP!$B$2:$L$2,1)),""))))) -> L | AF21: 高分 | AH21: 9 | AI21: 9
S22: 7 | X22: 连杆部件衬套内径衬套内孔直径＜46.023 | Y22: 连杆部件衬套内径衬套内孔直径＜46.023 | Z22: 2 | AA22: 按Q/YC 2511《曲柄连杆系统开发规范》控制间隙 | AB22: 按Q/YC 2511《曲柄连杆系统开发规范》控制间隙 | AC22: 4 | AD22: =IF(S22=1,"L",IF(AND(1<S22,S22<=3),INDEX(AP!$B$41:$L$51,MATCH(算分!Z22,AP!$B$41:$B$51,1),MATCH(算分!AC22,AP!$B$41:$L$41,1)),IF(AND(3<S22,S22<=6),INDEX(AP!$B$28:$L$38,MATCH(算分!Z22,AP!$B$28:$B$38,1),MATCH(算分!AC22,AP!$B$28:$L$28,1)),IF(AND(6<S22,S22<=8),INDEX(AP!$B$15:$L$25,MATCH(算分!Z22,AP!$B$15:$B$25,1),MATCH(算分!AC22,AP!$B$15:$L$15,1)),IF(AND(8<S22,S22<=10),INDEX(AP!$B$2:$L$12,MATCH(算分!Z22,AP!$B$2:$B$12,1),MATCH(算分!AC22,AP!$B$2:$L$2,1)),""))))) -> L | AF22: 高分 | AH22: 10 | AI22: 10
S23: 7 | X23: 连杆部件洁度＞108mg，导致轴瓦拉伤抱死 | Y23: 连杆部件洁度＞108mg，导致轴瓦拉伤抱死 | Z23: 3 | AA23: 图纸按Q/YC 11 清洁度要求执行 | AB23: 图纸按Q/YC 11 清洁度要求执行 | AC23: 4 | AD23: =IF(S23=1,"L",IF(AND(1<S23,S23<=3),INDEX(AP!$B$41:$L$51,MATCH(算分!Z23,AP!$B$41:$B$51,1),MATCH(算分!AC23,AP!$B$41:$L$41,1)),IF(AND(3<S23,S23<=6),INDEX(AP!$B$28:$L$38,MATCH(算分!Z23,AP!$B$28:$B$38,1),MATCH(算分!AC23,AP!$B$28:$L$28,1)),IF(AND(6<S23,S23<=8),INDEX(AP!$B$15:$L$25,MATCH(算分!Z23,AP!$B$15:$B$25,1),MATCH(算分!AC23,AP!$B$15:$L$15,1)),IF(AND(8<S23,S23<=10),INDEX(AP!$B$2:$L$12,MATCH(算分!Z23,AP!$B$2:$B$12,1),MATCH(算分!AC23,AP!$B$2:$L$2,1)),""))))) -> L | AH23: 11 | AI23: 11
S24: 7 | X24: CAE计算曲轴圆角强度安全系数＜1.2，导致曲轴断裂 | Y24: CAE计算曲轴圆角强度安全系数＜1.2，导致曲轴断裂 | Z24: 3 | AA24: 1、曲轴材料选择42CrMo；2、CAE计算曲轴圆角强度安全系数≥1.2 | AB24: 1、曲轴材料选择42CrMo；2、CAE计算曲轴圆角强度安全系数≥1.2 | AC24: 4 | AD24: =IF(S24=1,"L",IF(AND(1<S24,S24<=3),INDEX(AP!$B$41:$L$51,MATCH(算分!Z24,AP!$B$41:$B$51,1),MATCH(算分!AC24,AP!$B$41:$L$41,1)),IF(AND(3<S24,S24<=6),INDEX(AP!$B$28:$L$38,MATCH(算分!Z24,AP!$B$28:$B$38,1),MATCH(算分!AC24,AP!$B$28:$L$28,1)),IF(AND(6<S24,S24<=8),INDEX(AP!$B$15:$L$25,MATCH(算分!Z24,AP!$B$15:$B$25,1),MATCH(算分!AC24,AP!$B$15:$L$15,1)),IF(AND(8<S24,S24<=10),INDEX(AP!$B$2:$L$12,MATCH(算分!Z24,AP!$B$2:$B$12,1),MATCH(算分!AC24,AP!$B$2:$L$2,1)),""))))) -> L | AF24: 高分 | AH24: 12 | AI24: 12
S25: 7 | X25: 曲轴颗粒度＞600μm，杂质质量＞30mg；导致烧瓦 | Y25: 曲轴颗粒度＞600μm，杂质质量＞30mg；导致烧瓦 | Z25: 3 | AA25: 图纸按Q/YC 11 清洁度要求执行 | AB25: 图纸按Q/YC 11 清洁度要求执行 | AC25: 4 | AD25: =IF(S25=1,"L",IF(AND(1<S25,S25<=3),INDEX(AP!$B$41:$L$51,MATCH(算分!Z25,AP!$B$41:$B$51,1),MATCH(算分!AC25,AP!$B$41:$L$41,1)),IF(AND(3<S25,S25<=6),INDEX(AP!$B$28:$L$38,MATCH(算分!Z25,AP!$B$28:$B$38,1),MATCH(算分!AC25,AP!$B$28:$L$28,1)),IF(AND(6<S25,S25<=8),INDEX(AP!$B$15:$L$25,MATCH(算分!Z25,AP!$B$15:$B$25,1),MATCH(算分!AC25,AP!$B$15:$L$15,1)),IF(AND(8<S25,S25<=10),INDEX(AP!$B$2:$L$12,MATCH(算分!Z25,AP!$B$2:$B$12,1),MATCH(算分!AC25,AP!$B$2:$L$2,1)),""))))) -> L | AH25: 13 | AI25: 13
S26: 7 | X26: 曲轴轴颈未淬火 或硬度不在53-59HRC范围；导致曲轴磨损，烧瓦 | Y26: 曲轴轴颈未淬火 或硬度不在53-59HRC范围；导致曲轴磨损，烧瓦 | Z26: 1 | AA26: 按曲轴设计规范 | AB26: 按曲轴设计规范 | AC26: 6 | AD26: =IF(S26=1,"L",IF(AND(1<S26,S26<=3),INDEX(AP!$B$41:$L$51,MATCH(算分!Z26,AP!$B$41:$B$51,1),MATCH(算分!AC26,AP!$B$41:$L$41,1)),IF(AND(3<S26,S26<=6),INDEX(AP!$B$28:$L$38,MATCH(算分!Z26,AP!$B$28:$B$38,1),MATCH(算分!AC26,AP!$B$28:$L$28,1)),IF(AND(6<S26,S26<=8),INDEX(AP!$B$15:$L$25,MATCH(算分!Z26,AP!$B$15:$B$25,1),MATCH(算分!AC26,AP!$B$15:$L$15,1)),IF(AND(8<S26,S26<=10),INDEX(AP!$B$2:$L$12,MATCH(算分!Z26,AP!$B$2:$B$12,1),MATCH(算分!AC26,AP!$B$2:$L$2,1)),""))))) -> L | AF26: 高分 | AH26: 14 | AI26: 14
S27: 7 | X27: 轴瓦內圆表面硬度＜70Hv5，轴瓦磨损甚至烧瓦； | Y27: 轴瓦內圆表面硬度＜70Hv5，轴瓦磨损甚至烧瓦； | Z27: 1 | AA27: 按轴瓦设计规范控制硬度 | AB27: 按轴瓦设计规范控制硬度 | AC27: 4 | AD27: =IF(S27=1,"L",IF(AND(1<S27,S27<=3),INDEX(AP!$B$41:$L$51,MATCH(算分!Z27,AP!$B$41:$B$51,1),MATCH(算分!AC27,AP!$B$41:$L$41,1)),IF(AND(3<S27,S27<=6),INDEX(AP!$B$28:$L$38,MATCH(算分!Z27,AP!$B$28:$B$38,1),MATCH(算分!AC27,AP!$B$28:$L$28,1)),IF(AND(6<S27,S27<=8),INDEX(AP!$B$15:$L$25,MATCH(算分!Z27,AP!$B$15:$B$25,1),MATCH(算分!AC27,AP!$B$15:$L$15,1)),IF(AND(8<S27,S27<=10),INDEX(AP!$B$2:$L$12,MATCH(算分!Z27,AP!$B$2:$B$12,1),MATCH(算分!AC27,AP!$B$2:$L$2,1)),""))))) -> L | AF27: 高分 | AH27: 15 | AI27: 15
S28: 7 | X28: 轴瓦厚度＞2.48，导致曲轴和轴瓦间隙小，油膜不足，烧瓦 | Y28: 轴瓦厚度＞2.48，导致曲轴和轴瓦间隙小，油膜不足，烧瓦 | Z28: 2 | AA28: 按Q/YC 2511《曲柄连杆系统开发规范》控制间隙 | AB28: 按Q/YC 2511《曲柄连杆系统开发规范》控制间隙 | AC28: 4 | AD28: =IF(S28=1,"L",IF(AND(1<S28,S28<=3),INDEX(AP!$B$41:$L$51,MATCH(算分!Z28,AP!$B$41:$B$51,1),MATCH(算分!AC28,AP!$B$41:$L$41,1)),IF(AND(3<S28,S28<=6),INDEX(AP!$B$28:$L$38,MATCH(算分!Z28,AP!$B$28:$B$38,1),MATCH(算分!AC28,AP!$B$28:$L$28,1)),IF(AND(6<S28,S28<=8),INDEX(AP!$B$15:$L$25,MATCH(算分!Z28,AP!$B$15:$B$25,1),MATCH(算分!AC28,AP!$B$15:$L$15,1)),IF(AND(8<S28,S28<=10),INDEX(AP!$B$2:$L$12,MATCH(算分!Z28,AP!$B$2:$B$12,1),MATCH(算分!AC28,AP!$B$2:$L$2,1)),""))))) -> L | AF28: 高分 | AH28: 16 | AI28: 16
S29: 7 | X29: 主轴瓦清洁度控制：颗粒度＞600μm，杂质质量＞19.2mg； | Y29: 主轴瓦清洁度控制：颗粒度＞600μm，杂质质量＞19.2mg； | Z29: 1 | AA29: 图纸按Q/YC 11 清洁度要求执行 | AB29: 图纸按Q/YC 11 清洁度要求执行 | AC29: 5 | AD29: =IF(S29=1,"L",IF(AND(1<S29,S29<=3),INDEX(AP!$B$41:$L$51,MATCH(算分!Z29,AP!$B$41:$B$51,1),MATCH(算分!AC29,AP!$B$41:$L$41,1)),IF(AND(3<S29,S29<=6),INDEX(AP!$B$28:$L$38,MATCH(算分!Z29,AP!$B$28:$B$38,1),MATCH(算分!AC29,AP!$B$28:$L$28,1)),IF(AND(6<S29,S29<=8),INDEX(AP!$B$15:$L$25,MATCH(算分!Z29,AP!$B$15:$B$25,1),MATCH(算分!AC29,AP!$B$15:$L$15,1)),IF(AND(8<S29,S29<=10),INDEX(AP!$B$2:$L$12,MATCH(算分!Z29,AP!$B$2:$B$12,1),MATCH(算分!AC29,AP!$B$2:$L$2,1)),""))))) -> L | AH29: 17 | AI29: 17
S30: 7 | X30: 轴瓦內圆表面硬度＜70Hv5，轴瓦磨损甚至烧瓦； | Y30: 轴瓦內圆表面硬度＜70Hv5，轴瓦磨损甚至烧瓦； | Z30: 1 | AA30: 按轴瓦设计规范控制硬度 | AB30: 按轴瓦设计规范控制硬度 | AC30: 4 | AD30: =IF(S30=1,"L",IF(AND(1<S30,S30<=3),INDEX(AP!$B$41:$L$51,MATCH(算分!Z30,AP!$B$41:$B$51,1),MATCH(算分!AC30,AP!$B$41:$L$41,1)),IF(AND(3<S30,S30<=6),INDEX(AP!$B$28:$L$38,MATCH(算分!Z30,AP!$B$28:$B$38,1),MATCH(算分!AC30,AP!$B$28:$L$28,1)),IF(AND(6<S30,S30<=8),INDEX(AP!$B$15:$L$25,MATCH(算分!Z30,AP!$B$15:$B$25,1),MATCH(算分!AC30,AP!$B$15:$L$15,1)),IF(AND(8<S30,S30<=10),INDEX(AP!$B$2:$L$12,MATCH(算分!Z30,AP!$B$2:$B$12,1),MATCH(算分!AC30,AP!$B$2:$L$2,1)),""))))) -> L | AF30: 高分 | AH30: 18 | AI30: 18
S31: 7 | X31: 主轴瓦清洁度控制：颗粒度＞600μm，杂质质量＞19.2mg； | Y31: 主轴瓦清洁度控制：颗粒度＞600μm，杂质质量＞19.2mg； | Z31: 1 | AA31: 图纸按Q/YC 11 清洁度要求执行 | AB31: 图纸按Q/YC 11 清洁度要求执行 | AC31: 5 | AD31: =IF(S31=1,"L",IF(AND(1<S31,S31<=3),INDEX(AP!$B$41:$L$51,MATCH(算分!Z31,AP!$B$41:$B$51,1),MATCH(算分!AC31,AP!$B$41:$L$41,1)),IF(AND(3<S31,S31<=6),INDEX(AP!$B$28:$L$38,MATCH(算分!Z31,AP!$B$28:$B$38,1),MATCH(算分!AC31,AP!$B$28:$L$28,1)),IF(AND(6<S31,S31<=8),INDEX(AP!$B$15:$L$25,MATCH(算分!Z31,AP!$B$15:$B$25,1),MATCH(算分!AC31,AP!$B$15:$L$15,1)),IF(AND(8<S31,S31<=10),INDEX(AP!$B$2:$L$12,MATCH(算分!Z31,AP!$B$2:$B$12,1),MATCH(算分!AC31,AP!$B$2:$L$2,1)),""))))) -> L | AH31: 19 | AI31: 19
S32: 7 | X32: 主轴瓦受到的面压＞60MPa | Y32: 主轴瓦受到的面压＞60MPa | Z32: 2 | AA32: 仿真计算主轴瓦受到的面压控制＜60MPa | AB32: 仿真计算主轴瓦受到的面压控制＜60MPa | AC32: 4 | AD32: =IF(S32=1,"L",IF(AND(1<S32,S32<=3),INDEX(AP!$B$41:$L$51,MATCH(算分!Z32,AP!$B$41:$B$51,1),MATCH(算分!AC32,AP!$B$41:$L$41,1)),IF(AND(3<S32,S32<=6),INDEX(AP!$B$28:$L$38,MATCH(算分!Z32,AP!$B$28:$B$38,1),MATCH(算分!AC32,AP!$B$28:$L$28,1)),IF(AND(6<S32,S32<=8),INDEX(AP!$B$15:$L$25,MATCH(算分!Z32,AP!$B$15:$B$25,1),MATCH(算分!AC32,AP!$B$15:$L$15,1)),IF(AND(8<S32,S32<=10),INDEX(AP!$B$2:$L$12,MATCH(算分!Z32,AP!$B$2:$B$12,1),MATCH(算分!AC32,AP!$B$2:$L$2,1)),""))))) -> L | AF32: 高分 | AH32: 20 | AI32: 20
S33: 7 | X33: 轴瓦內圆表面硬度＜70Hv5，轴瓦磨损甚至烧瓦； | Y33: 轴瓦內圆表面硬度＜70Hv5，轴瓦磨损甚至烧瓦； | Z33: 1 | AA33: 按轴瓦设计规范控制硬度 | AB33: 按轴瓦设计规范控制硬度 | AC33: 4 | AD33: =IF(S33=1,"L",IF(AND(1<S33,S33<=3),INDEX(AP!$B$41:$L$51,MATCH(算分!Z33,AP!$B$41:$B$51,1),MATCH(算分!AC33,AP!$B$41:$L$41,1)),IF(AND(3<S33,S33<=6),INDEX(AP!$B$28:$L$38,MATCH(算分!Z33,AP!$B$28:$B$38,1),MATCH(算分!AC33,AP!$B$28:$L$28,1)),IF(AND(6<S33,S33<=8),INDEX(AP!$B$15:$L$25,MATCH(算分!Z33,AP!$B$15:$B$25,1),MATCH(算分!AC33,AP!$B$15:$L$15,1)),IF(AND(8<S33,S33<=10),INDEX(AP!$B$2:$L$12,MATCH(算分!Z33,AP!$B$2:$B$12,1),MATCH(算分!AC33,AP!$B$2:$L$2,1)),""))))) -> L | AF33: 高分 | AH33: 21 | AI33: 21
S34: 7 | X34: 主轴瓦清洁度控制：颗粒度＞600μm，杂质质量＞19.2mg； | Y34: 主轴瓦清洁度控制：颗粒度＞600μm，杂质质量＞19.2mg； | Z34: 1 | AA34: 图纸按Q/YC 11 清洁度要求执行 | AB34: 图纸按Q/YC 11 清洁度要求执行 | AC34: 5 | AD34: =IF(S34=1,"L",IF(AND(1<S34,S34<=3),INDEX(AP!$B$41:$L$51,MATCH(算分!Z34,AP!$B$41:$B$51,1),MATCH(算分!AC34,AP!$B$41:$L$41,1)),IF(AND(3<S34,S34<=6),INDEX(AP!$B$28:$L$38,MATCH(算分!Z34,AP!$B$28:$B$38,1),MATCH(算分!AC34,AP!$B$28:$L$28,1)),IF(AND(6<S34,S34<=8),INDEX(AP!$B$15:$L$25,MATCH(算分!Z34,AP!$B$15:$B$25,1),MATCH(算分!AC34,AP!$B$15:$L$15,1)),IF(AND(8<S34,S34<=10),INDEX(AP!$B$2:$L$12,MATCH(算分!Z34,AP!$B$2:$B$12,1),MATCH(算分!AC34,AP!$B$2:$L$2,1)),""))))) -> L | AH34: 22 | AI34: 22
S35: 7 | X35: 上连杆轴瓦受到的面压＞90MPa | Y35: 上连杆轴瓦受到的面压＞90MPa | Z35: 2 | AA35: 仿真计算上连杆轴瓦受到的面压＜90MPa | AB35: 仿真计算上连杆轴瓦受到的面压＜90MPa | AC35: 4 | AD35: =IF(S35=1,"L",IF(AND(1<S35,S35<=3),INDEX(AP!$B$41:$L$51,MATCH(算分!Z35,AP!$B$41:$B$51,1),MATCH(算分!AC35,AP!$B$41:$L$41,1)),IF(AND(3<S35,S35<=6),INDEX(AP!$B$28:$L$38,MATCH(算分!Z35,AP!$B$28:$B$38,1),MATCH(算分!AC35,AP!$B$28:$L$28,1)),IF(AND(6<S35,S35<=8),INDEX(AP!$B$15:$L$25,MATCH(算分!Z35,AP!$B$15:$B$25,1),MATCH(算分!AC35,AP!$B$15:$L$15,1)),IF(AND(8<S35,S35<=10),INDEX(AP!$B$2:$L$12,MATCH(算分!Z35,AP!$B$2:$B$12,1),MATCH(算分!AC35,AP!$B$2:$L$2,1)),""))))) -> L | AF35: 高分 | AH35: 23 | AI35: 23
S36: 7 | X36: 曲柄连杆模块总12mis＞1070ppm | Y36: 曲柄连杆模块总12mis＞1070ppm | Z36: 1 | AA36: 轴瓦內圆表面硬度＜70Hv5，轴瓦磨损甚至烧瓦； | AB36: 轴瓦內圆表面硬度＜70Hv5，轴瓦磨损甚至烧瓦； | AC36: 4 | AD36: =IF(S36=1,"L",IF(AND(1<S36,S36<=3),INDEX(AP!$B$41:$L$51,MATCH(算分!Z36,AP!$B$41:$B$51,1),MATCH(算分!AC36,AP!$B$41:$L$41,1)),IF(AND(3<S36,S36<=6),INDEX(AP!$B$28:$L$38,MATCH(算分!Z36,AP!$B$28:$B$38,1),MATCH(算分!AC36,AP!$B$28:$L$28,1)),IF(AND(6<S36,S36<=8),INDEX(AP!$B$15:$L$25,MATCH(算分!Z36,AP!$B$15:$B$25,1),MATCH(算分!AC36,AP!$B$15:$L$15,1)),IF(AND(8<S36,S36<=10),INDEX(AP!$B$2:$L$12,MATCH(算分!Z36,AP!$B$2:$B$12,1),MATCH(算分!AC36,AP!$B$2:$L$2,1)),""))))) -> L | AH36: 24 | AI36: 24
S37: 7 | X37: 轴瓦厚度＞：2.816，导致曲轴和轴瓦间隙小，油膜不足，烧瓦 | Y37: 轴瓦厚度＞：2.816，导致曲轴和轴瓦间隙小，油膜不足，烧瓦 | Z37: 2 | AA37: 按Q/YC 2511《曲柄连杆系统开发规范》控制间隙 | AB37: 按Q/YC 2511《曲柄连杆系统开发规范》控制间隙 | AC37: 4 | AD37: =IF(S37=1,"L",IF(AND(1<S37,S37<=3),INDEX(AP!$B$41:$L$51,MATCH(算分!Z37,AP!$B$41:$B$51,1),MATCH(算分!AC37,AP!$B$41:$L$41,1)),IF(AND(3<S37,S37<=6),INDEX(AP!$B$28:$L$38,MATCH(算分!Z37,AP!$B$28:$B$38,1),MATCH(算分!AC37,AP!$B$28:$L$28,1)),IF(AND(6<S37,S37<=8),INDEX(AP!$B$15:$L$25,MATCH(算分!Z37,AP!$B$15:$B$25,1),MATCH(算分!AC37,AP!$B$15:$L$15,1)),IF(AND(8<S37,S37<=10),INDEX(AP!$B$2:$L$12,MATCH(算分!Z37,AP!$B$2:$B$12,1),MATCH(算分!AC37,AP!$B$2:$L$2,1)),""))))) -> L | AF37: 高分 | AH37: 25 | AI37: 25
S38: 7 | X38: 轴瓦清洁度控制：颗粒度＞600μm，杂质质量＞19.2mg； | Y38: 轴瓦清洁度控制：颗粒度＞600μm，杂质质量＞19.2mg； | Z38: 1 | AA38: 图纸按Q/YC 11 清洁度要求执行 | AB38: 图纸按Q/YC 11 清洁度要求执行 | AC38: 5 | AD38: =IF(S38=1,"L",IF(AND(1<S38,S38<=3),INDEX(AP!$B$41:$L$51,MATCH(算分!Z38,AP!$B$41:$B$51,1),MATCH(算分!AC38,AP!$B$41:$L$41,1)),IF(AND(3<S38,S38<=6),INDEX(AP!$B$28:$L$38,MATCH(算分!Z38,AP!$B$28:$B$38,1),MATCH(算分!AC38,AP!$B$28:$L$28,1)),IF(AND(6<S38,S38<=8),INDEX(AP!$B$15:$L$25,MATCH(算分!Z38,AP!$B$15:$B$25,1),MATCH(算分!AC38,AP!$B$15:$L$15,1)),IF(AND(8<S38,S38<=10),INDEX(AP!$B$2:$L$12,MATCH(算分!Z38,AP!$B$2:$B$12,1),MATCH(算分!AC38,AP!$B$2:$L$2,1)),""))))) -> L | AH38: 26 | AI38: 26
S39: 7 | X39: 曲轴止推片清洁度控制：颗粒度＞600μm，杂质质量＜2mg； | Y39: 曲轴止推片清洁度控制：颗粒度＞600μm，杂质质量＜2mg； | Z39: 1 | AA39: 图纸按Q/YC 11 清洁度要求执行 | AB39: 图纸按Q/YC 11 清洁度要求执行 | AC39: 5 | AD39: =IF(S39=1,"L",IF(AND(1<S39,S39<=3),INDEX(AP!$B$41:$L$51,MATCH(算分!Z39,AP!$B$41:$B$51,1),MATCH(算分!AC39,AP!$B$41:$L$41,1)),IF(AND(3<S39,S39<=6),INDEX(AP!$B$28:$L$38,MATCH(算分!Z39,AP!$B$28:$B$38,1),MATCH(算分!AC39,AP!$B$28:$L$28,1)),IF(AND(6<S39,S39<=8),INDEX(AP!$B$15:$L$25,MATCH(算分!Z39,AP!$B$15:$B$25,1),MATCH(算分!AC39,AP!$B$15:$L$15,1)),IF(AND(8<S39,S39<=10),INDEX(AP!$B$2:$L$12,MATCH(算分!Z39,AP!$B$2:$B$12,1),MATCH(算分!AC39,AP!$B$2:$L$2,1)),""))))) -> L | AH39: 27 | AI39: 27
S40: 7 | X40: 曲柄连杆模块止推面压＞2.5MPa； | Y40: 曲柄连杆模块止推面压＞2.5MPa； | Z40: 2 | AA40: 仿真计算止推面压实际控制＜2.5MPa； | AB40: 仿真计算止推面压实际控制＜2.5MPa； | AC40: 4 | AD40: =IF(S40=1,"L",IF(AND(1<S40,S40<=3),INDEX(AP!$B$41:$L$51,MATCH(算分!Z40,AP!$B$41:$B$51,1),MATCH(算分!AC40,AP!$B$41:$L$41,1)),IF(AND(3<S40,S40<=6),INDEX(AP!$B$28:$L$38,MATCH(算分!Z40,AP!$B$28:$B$38,1),MATCH(算分!AC40,AP!$B$28:$L$28,1)),IF(AND(6<S40,S40<=8),INDEX(AP!$B$15:$L$25,MATCH(算分!Z40,AP!$B$15:$B$25,1),MATCH(算分!AC40,AP!$B$15:$L$15,1)),IF(AND(8<S40,S40<=10),INDEX(AP!$B$2:$L$12,MATCH(算分!Z40,AP!$B$2:$B$12,1),MATCH(算分!AC40,AP!$B$2:$L$2,1)),""))))) -> L | AF40: 高分 | AH40: 28 | AI40: 28
S41: 7 | X41: 曲柄连杆模块止推片常用转速线速度＞15m/s | Y41: 曲柄连杆模块止推片常用转速线速度＞15m/s | Z41: 2 | AA41: 曲柄连杆模块止推片常用转速线速度控制＜15m/s | AB41: 曲柄连杆模块止推片常用转速线速度控制＜15m/s | AC41: 4 | AD41: =IF(S41=1,"L",IF(AND(1<S41,S41<=3),INDEX(AP!$B$41:$L$51,MATCH(算分!Z41,AP!$B$41:$B$51,1),MATCH(算分!AC41,AP!$B$41:$L$41,1)),IF(AND(3<S41,S41<=6),INDEX(AP!$B$28:$L$38,MATCH(算分!Z41,AP!$B$28:$B$38,1),MATCH(算分!AC41,AP!$B$28:$L$28,1)),IF(AND(6<S41,S41<=8),INDEX(AP!$B$15:$L$25,MATCH(算分!Z41,AP!$B$15:$B$25,1),MATCH(算分!AC41,AP!$B$15:$L$15,1)),IF(AND(8<S41,S41<=10),INDEX(AP!$B$2:$L$12,MATCH(算分!Z41,AP!$B$2:$B$12,1),MATCH(算分!AC41,AP!$B$2:$L$2,1)),""))))) -> L | AF41: 高分 | AH41: 29 | AI41: 29
S42: 5 | X42: 活塞环总弹力系数＞0.75N/mm，运动副表面粗糙度＞Rz4 | Y42: 活塞环总弹力系数＞0.75N/mm，运动副表面粗糙度＞Rz4 | Z42: 3 | AA42: 设计阶段校准总弹力系数＜0.75N/mm，校准表面粗糙度＜Rz4 | AB42: 设计阶段校准总弹力系数＜0.75N/mm，校准表面粗糙度＜Rz4 | AC42: 3 | AD42: =IF(S42=1,"L",IF(AND(1<S42,S42<=3),INDEX(AP!$B$41:$L$51,MATCH(算分!Z42,AP!$B$41:$B$51,1),MATCH(算分!AC42,AP!$B$41:$L$41,1)),IF(AND(3<S42,S42<=6),INDEX(AP!$B$28:$L$38,MATCH(算分!Z42,AP!$B$28:$B$38,1),MATCH(算分!AC42,AP!$B$28:$L$28,1)),IF(AND(6<S42,S42<=8),INDEX(AP!$B$15:$L$25,MATCH(算分!Z42,AP!$B$15:$B$25,1),MATCH(算分!AC42,AP!$B$15:$L$15,1)),IF(AND(8<S42,S42<=10),INDEX(AP!$B$2:$L$12,MATCH(算分!Z42,AP!$B$2:$B$12,1),MATCH(算分!AC42,AP!$B$2:$L$2,1)),""))))) -> L | AH42: 30 | AI42: 30
S43: 5 | X43: 活塞环总弹力系数＞0.75N/mm，运动副表面粗糙度＞Rz4 | Y43: 活塞环总弹力系数＞0.75N/mm，运动副表面粗糙度＞Rz4 | Z43: 3 | AA43: 设计阶段校准总弹力系数＜0.75N/mm，校准表面粗糙度＜Rz4 | AB43: 设计阶段校准总弹力系数＜0.75N/mm，校准表面粗糙度＜Rz4 | AC43: 3 | AD43: =IF(S43=1,"L",IF(AND(1<S43,S43<=3),INDEX(AP!$B$41:$L$51,MATCH(算分!Z43,AP!$B$41:$B$51,1),MATCH(算分!AC43,AP!$B$41:$L$41,1)),IF(AND(3<S43,S43<=6),INDEX(AP!$B$28:$L$38,MATCH(算分!Z43,AP!$B$28:$B$38,1),MATCH(算分!AC43,AP!$B$28:$L$28,1)),IF(AND(6<S43,S43<=8),INDEX(AP!$B$15:$L$25,MATCH(算分!Z43,AP!$B$15:$B$25,1),MATCH(算分!AC43,AP!$B$15:$L$15,1)),IF(AND(8<S43,S43<=10),INDEX(AP!$B$2:$L$12,MATCH(算分!Z43,AP!$B$2:$B$12,1),MATCH(算分!AC43,AP!$B$2:$L$2,1)),""))))) -> L | AH43: 31 | AI43: 31
...

Sheet AP
E1: FMEA-AP
A2: S | B2: D O | C2: 1 | D2: 2 | E2: 3 | F2: 4 | G2: 5 | H2: 6 | I2: 7 | J2: 8 | K2: 9 | L2: 10
A3: 9-10 | B3: 1 | C3: L | D3: L | E3: L | F3: L | G3: L | H3: L | I3: L | J3: L | K3: L | L3: L
B4: 2 | C4: L | D4: L | E4: L | F4: L | G4: M | H4: M | I4: H | J4: H | K4: H | L4: H
B5: 3 | C5: L | D5: L | E5: L | F5: L | G5: M | H5: M | I5: H | J5: H | K5: H | L5: H
B6: 4 | C6: M | D6: H | E6: H | F6: H | G6: H | H6: H | I6: H | J6: H | K6: H | L6: H
B7: 5 | C7: M | D7: H | E7: H | F7: H | G7: H | H7: H | I7: H | J7: H | K7: H | L7: H
B8: 6 | C8: H | D8: H | E8: H | F8: H | G8: H | H8: H | I8: H | J8: H | K8: H | L8: H
B9: 7 | C9: H | D9: H | E9: H | F9: H | G9: H | H9: H | I9: H | J9: H | K9: H | L9: H
B10: 8 | C10: H | D10: H | E10: H | F10: H | G10: H | H10: H | I10: H | J10: H | K10: H | L10: H
B11: 9 | C11: H | D11: H | E11: H | F11: H | G11: H | H11: H | I11: H | J11: H | K11: H | L11: H
B12: 10 | C12: H | D12: H | E12: H | F12: H | G12: H | H12: H | I12: H | J12: H | K12: H | L12: H
A15: S | B15: D O | C15: 1 | D15: 2 | E15: 3 | F15: 4 | G15: 5 | H15: 6 | I15: 7 | J15: 8 | K15: 9 | L15: 10
A16: 7-8 | B16: 1 | C16: L | D16: L | E16: L | F16: L | G16: L | H16: L | I16: L | J16: L | K16: L | L16: L
B17: 2 | C17: L | D17: L | E17: L | F17: L | G17: M | H17: M | I17: H | J17: H | K17: H | L17: H
B18: 3 | C18: L | D18: L | E18: L | F18: L | G18: M | H18: M | I18: H | J18: H | K18: H | L18: H
A19: 44020 | B19: 4 | C19: M | D19: M | E19: M | F19: M | G19: M | H19: M | I19: H | J19: H | K19: H | L19: H
B20: 5 | C20: M | D20: M | E20: M | F20: M | G20: M | H20: M | I20: H | J20: H | K20: H | L20: H
B21: 6 | C21: M | D21: H | E21: H | F21: H | G21: H | H21: H | I21: H | J21: H | K21: H | L21: H
B22: 7 | C22: M | D22: H | E22: H | F22: H | G22: H | H22: H | I22: H | J22: H | K22: H | L22: H
B23: 8 | C23: H | D23: H | E23: H | F23: H | G23: H | H23: H | I23: H | J23: H | K23: H | L23: H
B24: 9 | C24: H | D24: H | E24: H | F24: H | G24: H | H24: H | I24: H | J24: H | K24: H | L24: H
B25: 10 | C25: H | D25: H | E25: H | F25: H | G25: H | H25: H | I25: H | J25: H | K25: H | L25: H
A28: S | B28: D O | C28: 1 | D28: 2 | E28: 3 | F28: 4 | G28: 5 | H28: 6 | I28: 7 | J28: 8 | K28: 9 | L28: 10
A29: 4-6 | B29: 1 | C29: L | D29: L | E29: L | F29: L | G29: L | H29: L | I29: L | J29: L | K29: L | L29: L
B30: 2 | C30: L | D30: L | E30: L | F30: L | G30: L | H30: L | I30: L | J30: L | K30: L | L30: L
B31: 3 | C31: L | D31: L | E31: L | F31: L | G31: L | H31: L | I31: L | J31: L | K31: L | L31: L
B32: 4 | C32: L | D32: L | E32: L | F32: L | G32: L | H32: L | I32: M | J32: M | K32: M | L32: M
B33: 5 | C33: L | D33: L | E33: L | F33: L | G33: L | H33: L | I33: M | J33: M | K33: M | L33: M
B34: 6 | C34: L | D34: M | E34: M | F34: M | G34: M | H34: M | I34: M | J34: M | K34: M | L34: M
B35: 7 | C35: L | D35: M | E35: M | F35: M | G35: M | H35: M | I35: M | J35: M | K35: M | L35: M
B36: 8 | C36: M | D36: M | E36: M | F36: M | G36: H | H36: H | I36: H | J36: H | K36: H | L36: H
B37: 9 | C37: M | D37: M | E37: M | F37: M | G37: H | H37: H | I37: H | J37: H | K37: H | L37: H
B38: 10 | C38: M | D38: M | E38: M | F38: M | G38: H | H38: H | I38: H | J38: H | K38: H | L38: H
A41: S | B41: D O | C41: 1 | D41: 2 | E41: 3 | F41: 4 | G41: 5 | H41: 6 | I41: 7 | J41: 8 | K41: 9 | L41: 10
A42: 2-3 | B42: 1 | C42: L | D42: L | E42: L | F42: L | G42: L | H42: L | I42: L | J42: L | K42: L | L42: L
B43: 2 | C43: L | D43: L | E43: L | F43: L | G43: L | H43: L | I43: L | J43: L | K43: L | L43: L
B44: 3 | C44: L | D44: L | E44: L | F44: L | G44: L | H44: L | I44: L | J44: L | K44: L | L44: L
B45: 4 | C45: L | D45: L | E45: L | F45: L | G45: L | H45: L | I45: L | J45: L | K45: L | L45: L
B46: 5 | C46: L | D46: L | E46: L | F46: L | G46: L | H46: L | I46: L | J46: L | K46: L | L46: L
...

Sheet 更改控制页 
A1: 广西玉柴机器股份有限公司 Guangxi Yuchai Machinery Co.,Ltd.
A2: 记录编号：QM/YCF13-70-01-870 | C2: 更改控制页
A3: 序号 | B3: 修订项 | C3: 修订前内容 | D3: 修订后内容 | E3: 修订人 | F3: 批准人 | G3: 修订时间
A4: 无 | B4: 无 | C4: 无 | D4: 无 | E4: 无 | F4: 无 | G4: 无
F29: =2890+20 -> 2910

Sheet P图-0530
A1: 步骤三 P图
A2: 噪音
A3: 噪音1：子系统间的变化，零件加工的差异（a、子系统输出偏差对系统的影响；b、接口偏差产生的影响；c、影响一致性的参数，制造装配的影响，识别生产加工的能力，如果能力不足要在图纸上进行补偿补充；d、出现过问题的需要优先）（供应商取水平最低的） 标准需要和生产确认是否符合，不符合按实际生产填写，不满足按过渡标准执行；-需要识别参数对功能的影响 | E3: 噪音2 | F3: 噪音3 | G3: 噪音4 | H3: 噪音5
A4: 个体化差异（生产控制的差异） | E4: 随时间变化（80万公里） | F4: 顾客使用 | G4: 外部环境 | H4: 系统交互作用（其他子系统不利的因素）
A5: 1、影响动力性： 曲柄连杆模块压缩比偏差±0.1 2、影响经济性/摩擦功： 1）（活塞环组件）总弹力系数：0.75N/mm 2）曲柄连杆模块运动副表面摩擦系数≤0.1 3、影响机油耗与窜气量： 1）曲柄连杆模块（活塞）外圆摩擦副型线±0.015； 2）曲柄连杆模块（活塞环与活塞第一环槽）梯角配合控制：±13′ 3）曲柄连杆模块（活塞与活塞环组件轴向）间隙控制mm：气环：0.12±0.02、刮油环：0.08±0.02、油环部件：0.05±0.02 4）曲柄连杆模块（活塞环组件闭口间隙）通路面积：1.14~1.52mm^2 5）曲柄连杆模块（活塞与活塞环组）配合面平行度：0.05 | E5: 1、运动副随时间磨损： 轴瓦和曲轴的间隙磨损≤1μm/100h， 曲柄连杆模块的的曲轴组件（止推片）铝合金层磨损速率≤20μm/100h 4、曲柄连杆模块的（活塞）积碳量速率≤TBD | F5: 1、在节气门后压力≥-28kPa，（-20~-10）kpa工况占比≤18%，（-00~-10）kpa工况占比≤21%，正压占比≥60% 2、频繁离合冲击、频繁启停（2次/min或10万/3 3、低档下坡发动机超速：2860rpm/30min，3300rpm/10s 4、燃油品质含硫量50ppm，含水量＞300ppm,颗粒度 ＞19级@14μm（c）＞23级@6μm（c）＞24级@4μm（c） | G5: 1、温度最低-35℃、最高温度50℃、湿度75%（96h盐雾试验合格） | H5: 1、燃烧子系统对曲柄连杆模块的活塞顶面热流量（5.3kw、气体爆压≤210bar、燃烧物成分中酸、水对活塞的腐蚀（腐蚀量化TBD）； 2、动力输出系统对曲柄连杆模块（曲轴及止推片）的轴向冲击作用最大9600N； 3、燃烧子系统缸内压力缸内负压最大-28kPa,占比≤39%，对曲柄连杆模块的（活塞环与活塞环槽）密封性能负面影响； 4、润滑子系统清洁度对曲柄连杆模块（轴瓦表面工作质量）的影响：颗粒度600μm，杂质质量202.6mg； 5、流量波动：不同转速下润滑油（喷嘴）最大流量4.8L/min，最小机油压力150kPa@800r/min、250kPa@1200r/min、400kPa@2200r/min（参考K8-1302-2018-02）； 6、曲通子系统空滤过滤效率最小99.7%时，空气清洁度对对曲柄连杆模块（活塞环）运动副的磨损影响：TBD 7、整机框架子系统（缸套）对曲柄连杆模块（活塞环）的冷却影响：TBD
A6: 输入 | C6: 系统或项目 | H6: 预期输出
A7: 工作输入： 1、缸内最大爆压210bar（缸内压力曲线） 2、活塞顶面热流量5.3kw（缸内温度曲线、缸内传热系数曲线） | C7: 曲柄连杆模块 | H7: 1、均匀稳定输出功率和扭矩： 1.1、 最大功率257kw/2200(r/min) 1.2、均匀稳定输出最大扭矩： 最大扭矩1500N.m@(1200~1600)r/min 2、机械转化效率≥98.58%。
A8: 功能 | C8: 功能性要求 | D8: 功能性要求 | E8: 控制因素 | G8: 非功能要求 | H8: 非预期输出
A9: 将燃烧产生的爆压压力通过活塞往复运动转化为曲轴旋转运动对外输出功率和扭矩 | C9: 1、输出扭矩和功率：最大扭矩1500N.m@(1200~1600)r/min；低速扭矩≥1000N.m@800r/min；最大功率257kw/2200(r/min)；2、满足10^7循环次数使用要求。；3在全寿命周期内和额定转速条件下输出扭矩和功率变化量≤0.5%；4、标定点摩擦功≤3.7kw。 | D9: 1、输出扭矩和功率：最大扭矩1500N.m@(1200~1600)r/min；低速扭矩≥1000N.m@800r/min；最大功率257kw/2200(r/min)； 2、转化效率98.58%。 | E9: 主要功能： 1、曲柄连杆模块提供燃烧初始压力,压缩比19.3 2、摩擦功：曲柄连杆模块标定点≤3.7kW；BTE点≤1.7kW。 | G9: 1、热动子系统内部模块接口 1.1 曲轴连杆模块和飞轮及齿圈模块接口：8XM16X70 | H9: 1、NVH：扭转振幅：单阶≤0.2 deg，合成阶≤0.5deg 2、最大瞬间扭矩：6530N.m 3、机油消耗： ①全速全负荷机油消耗率0.06~0.12（g/ kW·h），2000h耐久后≤0.15（g/ kW·h）； ②在节气门后压力≥-28kPa，（-20~-10）kpa工况占比≤18%，（-00~-10）kpa工况占比≤21%，正压占比≥60%：48h模拟路谱工况机燃比：≤0.11% ； ③实际道路40000km≤0.06%； 4、可靠性前标定点活塞漏气量(50~120)L/min，可靠性后＜130)L/min； 5、摩擦功在标定点≤3.7kW；BTE点≤1.7kW。
K10: 各种怠速/低速负压混合工况下的路谱机燃比≤0.3%（任务书暂无定义，暂按目前市场可接受程度）
E12: 噪音1： 1、曲柄连杆模块（活塞燃烧室）容积（±0.8mL)、死区容积：-1.45~1.45mL 2、1）曲柄连杆模块（活塞环组件）总弹力系数：0.75N/mm；2）运动副表面粗糙度Rz4 3、1）曲柄连杆模块（活塞）摩擦副外圆型线±0.015，运动副外圆面压≤40MPa 2）曲柄连杆模块（活塞与活塞环）梯角配合控制：±13′ 3）曲柄连杆模块间隙（活塞与活塞环）公差控制：0.05mm 4）曲柄连杆模块（活塞环组件闭口间隙）通路面积：1.14~1.52mm^2 5）曲柄连杆模块(活塞与活塞环组件）配合面形位要求与粗糙度：跳动度0.05，周向直线度0.015，粗糙度Rz4 | G12: 1、热动子系统内部模块接口 1.2 曲轴连杆模块和减振器模块接口：①6XM14X34.5；②一缸上止点和销钉朝上对齐
E13: 噪音2： 1、①曲柄连杆模块的（曲轴颈）硬度53-59HRC，轴瓦硬度＞70Hv5，轴瓦摩擦系数0.026； ②曲柄连杆模块止推片铝合金层摩擦系数0.026； 2、曲柄连杆模块（活塞第一环槽）温度≤260℃； | G13: 1、热动子系统内部模块接口 1.3 曲轴连杆模块和油封模块接口：过盈量0.23，曲轴接触外径：85（-0.035,0），粗糙度控制带长度9mm
E14: 噪音3： 1、曲柄连杆模块（活塞环与活塞第一环槽）梯角配合控制：±13′、曲柄连杆模块（活塞环槽与活塞环）配合面形位要求与粗糙度：跳动度0.05，周向直线度0.015，粗糙度Rz4；（活塞环）总弹力系数：0.75N/mm；曲柄连杆模块（活塞与活塞环组件轴向）间隙控制mm：气环：0.12±0.02、刮油环：0.08±0.02、油环部件：0.05±0.02；曲柄连杆模块通路面积：1.14~1.52mm^2； 2、曲柄连杆模块止推承压能力≥2.5MPa； 3、曲柄连杆模块（连杆部件的大头）运动副变形量≤0.0192mm； 4、针对使用劣质燃油导致的活塞环腐蚀：曲柄连杆模块的活塞和活塞环组件表面增加磷化处理。 | G14: 2、热动子系统分解给曲柄连杆模块的接口需求 （1）曲柄连杆模块提供物理连接面1（轴瓦与机体）：直径93，宽度30.5，唇口宽度3.6，凸出量1.4，高度5 （2）曲柄连杆模块提供物理连接面2（止推片与机体）：外径124，厚度2.5 （3)曲柄连杆模块提供物理连接面3（活塞与机体）：外径109.89±0.009，高度110 （4）缸心距128
E15: 噪音4： 无
E16: 噪音5： 1、曲柄连杆模块温度场喉口温度≤360℃，火力岸≤280℃；疲劳安全系数≥1.2； 2、曲柄连杆模块（止推片）止推承压能力＞2.5MPa； 3、曲柄连杆模块（活塞环与活塞第一环槽）梯角配合控制：±13′、曲柄连杆模块（活塞环槽与活塞环）配合面形位要求与粗糙度：跳动度0.05，周向直线度0.015，粗糙度Rz4；（活塞环组件）总弹力系数：0.75N/mm；曲柄连杆模块（活塞与活塞环组件轴向）间隙控制mm：气环：0.12±0.02、刮油环：0.08±0.02、油环部件：0.05±0.02；曲柄连杆模块通路面积：1.14~1.52mm^2； 4、曲柄连杆模块清洁度控制：颗粒度≤600μm，杂质质量≤202.6mg（曲轴＜30，活塞＜24，主轴瓦＜19.2，连杆轴瓦：12.4，连杆部件＜108，活塞销＜9） 5、曲柄连杆模块（活塞）进油孔位置精度±0.5，曲轴连杆模块轴瓦内径间隙控制mm：0.024~0.088； 6、曲柄连杆模块（活塞环组件）：表面硬度800-1000HV； 7、曲柄连杆模块（活塞第一环槽位置）：12.12mm（低于水套高度） | G16: 2、热动子系统分解给曲柄连杆模块的接口需求 与润滑子系统的接口 曲柄连杆模块在进气侧提供与缸中心距离36X21.35的进油孔接口，同时给喷嘴提供＞3避让空间
E17: 非预期输出： 1、曲柄连杆模块不平衡量60g•cm（其中曲轴＜30，飞轮＜25），活塞连杆总成重量差＜30g，扭转振幅：单阶≤0.2 deg，合成阶≤0.5deg； 2、①曲柄连杆模块（活塞环组件）总弹力系数：0.75N/mm； ②曲柄连杆模块（活塞环与活塞第一环槽）梯角配合控制：±13′、曲柄连杆模块（活塞环槽与活塞环）配合面形位要求与粗糙度：跳动度0.05，周向直线度0.015，粗糙度Rz4； ③曲柄连杆模块（活塞与活塞环组件轴向）间隙控制mm：气环：0.12±0.02、刮油环：0.08±0.02、油环部件：0.05±0.02；曲柄连杆模块（活塞环槽与活塞环）配合面形位要求与粗糙度：跳动度0.05，周向直线度0.015，粗糙度Rz4； 3、曲柄连杆模块（活塞环组件闭口间隙）轴向通路面积：1.14~1.52mm^2 4、曲柄连杆模块（活塞环组件）总弹力系数：0.75N/mm,（活塞环组件外圆）总接触长度＜4.8mm、曲柄连杆模块（活塞环和活塞）运动副表面粗糙度Rz4，曲柄连杆模块曲轴组件运动副摩擦系数＜0.015；曲柄连杆模块活塞组件运动副摩擦系数＜0.1； | G17: 2、热动子系统分解给曲柄连杆模块的接口需求 与控制子系统的接口 曲轴对应发火间隔顺序为153624
E18: 模块内部间的接口控制： 1、活塞-活塞销：能传递210bar的爆压压力，并在0.007~0.022间隙（活塞销孔直径：46.007~46.016，销直径46~45.992）下不抱死 2、活塞销-衬套：能传递210bar的爆压压力，并在0.023~0.043间隙（活衬套内孔直径：46.023~46.037，销直径46~45.992）下不抱死 3-连杆轴瓦-曲轴：能传递210bar的爆压压力，并在0.024~0.088间隙（轴瓦厚度：2.5(-0.026,-0.016)，曲轴连杆轴颈直径81(-0.022,0)下保持转动灵活 4-主轴瓦-曲轴：能传递210bar的爆压压力，并在0.04~0.082间隙（轴瓦厚度：2.5(-0.02,-0.03)，曲轴连杆轴颈直径95(-0.022,0)下保持转动灵活 | G18: 2、热动子系统分解给曲柄连杆模块的接口需求 配气缸盖子系统接口 （1）提供正时齿轮安装螺纹孔：分布圆95,2-M6X1.5X9，正时信号定位销与一缸上止点成45° （2）提供气门让位避让空间（气门间隙）：进气门1，直径38.5，排气门2.3，直径35.5 （3）曲柄连杆最大长度：496.81~496.9045。
E19: 3、模块内部接口控制： 1）活塞-活塞销：间隙配合，活塞销孔尺寸，活塞销尺寸： | G19: 重量：曲柄连杆模块总重量≤72g 满足法规的无禁用物要求：无铅
E20: 3、模块内部接口控制： 2）连杆部件-活塞销：间隙配合，活塞销尺寸，连杆部件（内孔尺寸） | G20: 可靠性指标分解：总12mis≤1070ppm 活塞：12mis≤130 活塞销12mis≤80 连杆部件12mis ≤106 上连杆轴瓦12mis≤150 下连杆轴瓦12mis≤110 上主轴瓦12mis≤100 下主轴瓦12mis≤60 止推片12mis ≤107 曲轴12mis≤107 活塞环组件12mis≤120
E21: 3、模块内部接口控制： 3）连杆轴瓦-连杆部件：定位唇大小，位置 | G21: 成本：曲柄连杆模块总成本≤XX元 活塞 活塞销 连杆部件 上下连杆轴瓦 上下主轴瓦 上下止推片 曲轴 活塞环组件
E22: 3、模块内部接口控制： 4）连杆轴瓦-曲轴：间隙配合，连杆瓦尺寸：；曲轴轴颈尺寸：
E23: 3、模块内部接口控制： 5）主轴瓦-曲轴：间隙配合，主轴瓦尺寸：；曲轴轴颈尺寸：
E24: 3、模块内部接口控制： 6）止推片-曲轴：径向间隙配合：止推片内径：
E25: 3、模块内部接口控制： 7）活塞环-活塞环槽：活塞环径向、轴向尺寸，环槽径向，轴向尺寸

Sheet DFMEA-0530
A1: Design Failure Mode and Effects Analysis (Design FMEA) 设计失效模式及影响分析(设计FMEA)
A2: Planning and Preparation (Step 1) 策划与准备 （步骤一）
A3: Company Name: 公司名称: | I3: Product Type: 产品型号: | L3: K08-68 | R3: Subject: 项目: | W3: DFMEA Number: DFMEA 编号: | Y3: DF2209200002-015
A4: Production Location: 生产地址: | I4: PN: 零件号: | L4: A | R4: DFMEA Start Date: DFMEA 开始日期: | W4: DFMEA Revision No: DFMEA 版本号: | Y4: V1.0
A5: Customer Name: 顾客名称: | I5: Model Year / Program(s): 年型/项目: | R5: DFMEA Revision Date: DFMEA 修订日期: | T5: 未发布
A6: Customer PN: 顾客零件号: | I6: Confidentiality Level: 保密级别: | R6: Design Responsibility: 设计责任人: | T6: 韦良锦/结构开发部
A7: Customer Drawing Revision No: 顾客图纸版本号: | I7: Cross-Functional Team: 跨职能团队: | L7: 包毅
A9: Continuous Improvement 持续改善 | C9: Structure Analysis(Setp2) 结构分析（步骤二） | F9: Function Analysis (Step 3) 功能分析 （步骤三） | I9: Failure Analysis (Step 4) 失效分析 （步骤四） | M9: DFMEA Risk Analysis (Step 5) 设计 FMEA 风险分析 （步骤五） | R9: DFMEA Optimization (Step 6) 设计 FMEA 优化（步骤六） | AC9: Remark 备注
A10: Issues 问题# | B10: History/change Authorization (as Applicable) 历史/变更授权(适用时) | C10: 1. Next Higher Level 上一较高级别 | D10: 2. Focus Element 关注要素 | E10: 3. Next Lower Level or Characteristic Type 下一较低级别或特性类 | F10: 1. Next Higher Level Function and Requirement 上一较高级别功能和要求 | G10: 2. Focus Element Function and Requirement 关注要素功能和要求 | H10: 3. Next Lower Level Function and Requirement or Characteristic Type 下一较低级别功能和要求或特性类 | I10: 1. Failure effects(FE) to the Next Higher Level Element and/or End User 对于上一较高级别要素和/或最终用户的失效影响 (FE) | J10: Severity of FE(S) 失效影响的严重度 | K10: 2. Failure Mode(FM) of focus Element 关注要素的失效模式 (FM) | L10: 3. Failure Cause (FC) of the Next Lower Element or Characteristic 下一较低级别要素或特性的失效起因 (FC) | M10: Current Prevention Control(PC) of FC对失效起因的当前预防控制(PC) | N10: Occurrence(O) of FC 失效起因的频度(O) | O10: Current Detection Control(DC) of FC or FM失效起因或失效模式的当前探测控制(DC) | P10: Detection (D) of FC /FM 失效起因/失效模式的探测度 | Q10: DFMEA AP 设计FMEA措施优先级 | R10: DFMEA Preventive Action 预防措施 | S10: DFMEA Detection Action探测措施 | T10: Responsible Person’s Name 负责人姓名 | U10: Target Completion Date 目标完成日期 | V10: Status 状态 | W10: Action Taken with Pointer to Evidence 采取基于证据的措施 | X10: Completion Date 完成日期 | Y10: Severity(S)严重度 | Z10: Occurrence(O)发生度 | AA10: Detection (D) 探测度 | AB10: DFMEA AP措施优先级
C11: 热动转化子系 | D11: 曲柄连杆模块 | E11: 活塞 | F11: 主要功能：将热能转化成动能，均匀稳定输出扭矩要求：最大扭矩1500N.m@(1200~1600)r/min | G11: 主要功能：将热能转化成动能，均匀稳定输出扭矩要求：最大扭矩1500N.m@(1200~1600)r/min | H11: 活塞承受爆压，燃烧室的尺寸、形状与容积47.25±0.8mL | I11: 输出扭矩不足，在(1200~1600)r/min下输出最大扭矩＜1500N.m | J11: 7 | K11: 曲柄连杆模块：热动子系统形成燃烧腔不满足压缩比19±0.3要求 | L11: 活塞燃烧室的尺寸、形状轮廓不符合输入要求，容积不满足47.25±0.8mL要求 | M11: 设计三维测量校准燃烧室容积满足47.25±0.8mL | N11: 2 | O11: 整机压缩容积测试，容积满足要求 | P11: 2 | Q11: =算分!AD13 -> L
E12: 活塞 | F12: 足B10寿命＞80万公里，12MIS＜2170 | G12: B10寿命80万公里，12MIS≤1070ppm； | H12: 活塞：12mis≤130，B10寿命＞80万公里：安全系数＞1.2 | I12: 满足B10寿命＜80万公里，12MIS＞2170 | J12: 7 | K12: B10寿命＜80万公里，12MIS＞1070ppm； | L12: 活塞结构设计安全系数＜1.2 | M12: 1、设计阶段活塞CAE结构强度分析安全系数≥1.2 | N12: 2 | O12: 1-活塞单体试验-4 2-整机2000h可靠性试验-6 | P12: 4 | Q12: =算分!AD14 -> L
E13: 活塞 | H13: 活塞：12mis≤130，B10寿命＞80万公里：安全系数大禹1.2：活塞外径＜109.89±0.009不拉缸 | J13: 7 | L13: 活塞外径大于109.89±0.009，间隙不足导致拉缸 | M13: 活塞外径满足109.89±0.009（即与缸套间隙满足《曲柄连杆开发规范》规定的间隙） | N13: 2 | O13: 拉缸试验 | P13: 4 | Q13: =算分!AD15 -> L
E14: 活塞 | J14: 7 | L14: 1、活塞环组件与活塞轴向间隙控制＜要求mm：气环：0.12±0.02、刮油环：0.08±0.02、油环部件：0.05±0.02；导致卡环 | M14: 按Q/YC 2511《曲柄连杆系统开发规范 1、活塞环组件与活塞轴向间隙控制mm：气环：0.12±0.02、刮油环：0.08±0.02、油环部件：0.05±0.02 | N14: 2 | O14: 拉缸试验 | P14: 4 | Q14: =算分!AD16 -> L
E15: 活塞 | J15: 7 | L15: 活塞清洁度＞24mg，清洁度控制问题导致拉缸 | M15: 图纸按Q/YC 11 清洁度要求执行 | N15: 1 | O15: 整机性能试验 | P15: 5 | Q15: =算分!AD17 -> L
E16: 活塞 | J16: 7 | L16: 活塞销孔直径＜46.007，导致活塞销和销孔卡死（活塞销同此条） | M16: 按Q/YC 2511《曲柄连杆系统开发规范》控制间隙 | N16: 2 | O16: 高温拉缸试验 | P16: 4 | Q16: =算分!AD18 -> L
E17: 活塞销 | H17: 活塞销12mis≤80，B10寿命＞80万公里 | J17: 7 | L17: 活塞销安全系数＜1.2，导致活塞销断裂 | M17: 设计阶段活塞销CAE结构强度分析安全系数≥1.2 | N17: 1 | O17: 整机2000h可靠性试验 | P17: 6 | Q17: =算分!AD19 -> L
E18: 活塞销 | J18: 7 | L18: 活塞清洁度＞24mg，导致活塞销拉伤抱死 | M18: 图纸按Q/YC 11 清洁度要求执行 | N18: 1 | O18: 整机性能试验 | P18: 5 | Q18: =算分!AD20 -> L
E19: 连杆部件 | H19: 连杆部件12mis ≤106，B10寿命＞80万公里 | J19: 7 | L19: 连杆部件整体安全系数小于1.2，导致连杆断裂 | M19: 设计阶段连杆部件CAE结构强度分析安全系数≥1.2 | N19: 3 | O19: 2、整机耐久性试验 | P19: 4 | Q19: =算分!AD21 -> L
E20: 连杆部件 | J20: 7 | L20: 连杆部件衬套内径衬套内孔直径＜46.023 | M20: 按Q/YC 2511《曲柄连杆系统开发规范》控制间隙 | N20: 2 | O20: 高温拉缸试验 | P20: 4 | Q20: =算分!AD22 -> L
E21: 连杆部件 | J21: 7 | L21: 连杆部件洁度＞108mg，导致轴瓦拉伤抱死 | M21: 图纸按Q/YC 11 清洁度要求执行 | N21: 3 | O21: 整机性能试验 | P21: 4 | Q21: =算分!AD23 -> L
E22: 曲轴 | H22: 曲轴12mis≤107，B10寿命＞80万公里 | J22: 7 | L22: CAE计算曲轴圆角强度安全系数＜1.2，导致曲轴断裂 | M22: CAE计算曲轴圆角强度安全系数≥1.2 | N22: 3 | O22: 1-曲轴弯曲疲劳试验 2-整机2000h可靠性试验 | P22: 4 | Q22: =算分!AD24 -> L
E23: 曲轴 | J23: 7 | L23: 曲轴颗粒度＞600μm，杂质质量＞30mg；导致烧瓦 | M23: 图纸按Q/YC 11 清洁度要求执行 | N23: 3 | O23: 整机性能试验 | P23: 4 | Q23: =算分!AD25 -> L
E24: 曲轴 | J24: 7 | L24: 曲轴轴颈未淬火 或硬度＜53HRC范围；导致曲轴磨损，烧瓦 | M24: Q/YC 706.4《曲轴材料及热处理规范》，硬度≥53HRC | N24: 1 | O24: 整机2000h可靠性试验 | P24: 6 | Q24: =算分!AD26 -> L
E25: 上主轴瓦 | H25: 上主轴瓦12mis≤100，B10寿命＞80万公里； | J25: 7 | L25: 轴瓦內圆表面硬度＜70Hv5，轴瓦磨损甚至烧瓦； | M25: Q/YC 753.2-《轴瓦工程规范》，轴瓦硬度＞70Hv5 | N25: 1 | O25: 1-轴瓦材料性能测试 2-整机2000h可靠性试验 | P25: 4 | Q25: =算分!AD27 -> L
E26: 上主轴瓦 | J26: 7 | L26: 轴瓦厚度＞2.48，导致曲轴和轴瓦间隙小，油膜不足，烧瓦（曲轴主轴颈、上主轴瓦同此条） | M26: 1-按Q/YC 2511《曲柄连杆系统开发规范》控制间隙 2-轴瓦EHD计算满足仿真评价标准 | N26: 2 | O26: 整机外特性最高爆压测试 | P26: 4 | Q26: =算分!AD28 -> L
E27: 上主轴瓦 | J27: 7 | L27: 主轴瓦清洁度控制：颗粒度＞600μm，杂质质量＞19.2mg； | M27: 图纸按Q/YC 11 清洁度要求执行 | N27: 1 | O27: 整机性能试验 | P27: 5 | Q27: =算分!AD29 -> L
E28: 下主轴瓦 | H28: B10寿命＞80万公里；下主轴瓦12mis≤60 | J28: 7 | L28: 轴瓦內圆表面硬度＜70Hv5，轴瓦磨损甚至烧瓦； | M28: Q/YC 753.2-《轴瓦工程规范》，轴瓦硬度＞70Hv5 | N28: 1 | O28: 1-轴瓦材料性能测试 2-整机2000h可靠性试验 | P28: 4 | Q28: =算分!AD30 -> L
E29: 下主轴瓦 | J29: 7 | L29: 主轴瓦清洁度控制：颗粒度＞600μm，杂质质量＞19.2mg； | M29: 图纸按Q/YC 11 清洁度要求执行 | N29: 1 | O29: 整机性能试验 | P29: 5 | Q29: =算分!AD31 -> L
E30: 下主轴瓦 | J30: 7 | L30: 主轴瓦受到的面压＞60MPa | M30: 1-仿真计算主轴瓦受到的面压控制＜60MPa 2-2-按Q/YC 753.1《轴瓦设计规范》对轴瓦选型 | N30: 2 | O30: 1-合金镀层疲劳强度试验 2-整机2000h可靠性试验 | P30: 4 | Q30: =算分!AD32 -> L
E31: 上连杆轴瓦 | H31: 上连杆轴瓦12mis≤150，B10寿命＞80万公里； | J31: 7 | L31: 轴瓦內圆表面硬度＜70Hv5，轴瓦磨损甚至烧瓦； | M31: Q/YC 753.2-《轴瓦工程规范》，轴瓦硬度＞70Hv5 | N31: 1 | O31: 1-轴瓦材料性能测试 2-整机2000h可靠性试验 | P31: 4 | Q31: =算分!AD33 -> L
E32: 上连杆轴瓦 | J32: 7 | L32: 主轴瓦清洁度控制：颗粒度＞600μm，杂质质量＞19.2mg； | M32: 图纸按Q/YC 11 清洁度要求执行 | N32: 1 | O32: 整机性能试验 | P32: 5 | Q32: =算分!AD34 -> L
E33: 上连杆轴瓦 | J33: 7 | L33: 上连杆轴瓦受到的面压＞90MPa | M33: 1-仿真计算上连杆轴瓦受到的面压＜90MPa 2-按Q/YC 753.1《轴瓦设计规范》对轴瓦选型 | N33: 2 | O33: 1-合金镀层疲劳强度试验 2-整机2000h可靠性试验 | P33: 4 | Q33: =算分!AD35 -> L
E34: 下连杆轴瓦 | H34: 下连杆轴瓦12mis≤110，B10寿命＞80万公里； | J34: 7 | L34: 轴瓦內圆表面硬度＜70Hv5，轴瓦磨损甚至烧瓦； | M34: Q/YC 753.2-《轴瓦工程规范》，轴瓦硬度＞70Hv5 | N34: 1 | O34: 1-轴瓦材料性能测试 2-整机2000h可靠性试验 | P34: 4 | Q34: =算分!AD36 -> L
E35: 下连杆轴瓦 | J35: 7 | L35: 轴瓦厚度＞2.816，导致曲轴和轴瓦间隙小，油膜不足，烧瓦 （曲轴连杆轴颈、上连杆轴瓦同此条） | M35: 1-按Q/YC 2511《曲柄连杆系统开发规范》控制间隙 2-轴瓦EHD计算满足仿真评价标准 | N35: 2 | O35: 整机外特性最高爆压测试 | P35: 4 | Q35: =算分!AD37 -> L
E36: 下连杆轴瓦 | J36: 7 | L36: 轴瓦清洁度控制：颗粒度＞600μm，杂质质量＞19.2mg； | M36: 图纸按Q/YC 11 清洁度要求执行 | N36: 1 | O36: 整机性能试验 | P36: 5 | Q36: =算分!AD38 -> L
E37: 曲轴止推片 | H37: 曲轴止推片12mis≤110，B10寿命＞80万公里； | J37: 7 | L37: 曲轴止推片清洁度控制：颗粒度＞600μm，杂质质量＜2mg； | M37: 图纸按Q/YC 11 清洁度要求执行 | N37: 1 | O37: 整机性能试验 | P37: 5 | Q37: =算分!AD39 -> L
E38: 曲轴止推片 | J38: 7 | L38: 曲柄连杆模块止推面压＞2.5MPa； | M38: 仿真计算止推面压实际控制＜2.5MPa； | N38: 2 | O38: 1-合金镀层疲劳强度试验 2-2万公里道路试验 | P38: 4 | Q38: =算分!AD40 -> L
E39: 曲轴止推片 | J39: 7 | L39: 曲柄连杆模块止推片常用转速线速度＞15m/s | M39: 按724.1《曲轴止推片设计规范》，根据止推片线速度对止推片材料进行选型 | N39: 2 | O39: 1-耐磨性试验 2-2万公里道路试验 | P39: 4 | Q39: =算分!AD41 -> L
E40: 活塞环组件 | F40: 非预期输出： 摩擦功：热转化子系统标定点≤3.7kW；BTE点≤1.7kW； | G40: 曲柄连杆模块（活塞环组件）总弹力系数：0.75N/mm,（活塞环组件外圆）总接触长度＜4.8mm、曲柄连杆模块（活塞环和活塞）运动副表面粗糙度Rz4，曲柄连杆模块曲轴组件运动副摩擦系数＜0.015；曲柄连杆模块活塞组件运动副摩擦系数＜0.1； | H40: 1）活塞环组件总弹力系数＜0.75N/mm； 2）运动副表面粗糙度＜Rz4 | I40: 热转化子系统标定点＞3.7kW；BTE点＞1.7kW； | J40: 5 | K40: 曲柄连杆模块标定点＞3.7kW；BTE点＞1.7kW | L40: 活塞环总弹力系数＞0.75N/mm，运动副表面粗糙度＞Rz4 | M40: 设计阶段校准总弹力系数＜0.75N/mm，校准表面粗糙度＜Rz4 | N40: 3 | O40: 摩擦功试验 | P40: 3 | Q40: =算分!AD42 -> L
E41: 活塞环组件 | G41: 曲柄连杆模块（活塞环组件）总弹力系数：0.75N/mm,（活塞环组件外圆）总接触长度＜4.8mm、曲柄连杆模块（活塞环和活塞）运动副表面粗糙度Rz4，曲柄连杆模块曲轴组件运动副摩擦系数＜0.015；曲柄连杆模块活塞组件运动副摩擦系数＜0.1； | H41: 1）活塞环组件总弹力系数＜0.75N/mm； 2）运动副表面粗糙度＜Rz4 | J41: 5 | L41: 活塞环总弹力系数＞0.75N/mm，运动副表面粗糙度＞Rz4 | M41: 设计阶段校准总弹力系数＜0.75N/mm，校准表面粗糙度＜Rz4 | N41: 3 | O41: 摩擦功试验 | P41: 3 | Q41: =算分!AD43 -> L
...

Sheet 边界图
M1: 接口关系
M2: FORM | N2: TO | O2: 接口类型 | P2: 要求
M3: 整机框架子系统-曲轴箱（含吸油盘） | N3: 曲柄连杆模块-连杆部件 | O3: 物理连接：连杆部件运动轨迹与曲轴箱间隙配合 | P3: 连杆部件运动轨迹与曲轴箱（含吸油盆）间距＞5mm | Q3: 子系统分解
M4: 润滑子系统-机油液面 | N4: 曲柄连杆模块-连杆部件 | O4: 物理连接：连杆部件与机油液面间隙配合 | P4: 连杆部件与机油液面间隙＞5mm | Q4: 子系统分解
M5: 曲轴 | N5: 连杆部件 | O5: 物理连接：连杆部件与曲轴轴向间隙配合 | P5: 连杆部件与曲轴轴向间隙设计一定公差 | Q5: 子模块分解
M6: 活塞 | N6: 连杆部件 | O6: 物质交换：活塞将润滑油传递到连杆部件 | P6: 活塞通过内冷油道的出油口（油孔角）将润滑油传递到连杆部件小头区域 | Q6: 子模块分解
M7: 活塞 | N7: 连杆部件 | O7: 物理连接：连杆部件小头与活塞内腔间隙配合 | P7: 连杆部件小头与活塞内腔轴向间隙≥2mm，顶部≥5mm | Q7: 子模块分解
M8: 活塞销 | N8: 连杆部件 | O8: 物理连接：间隙配合 | P8: 连杆部件衬套和活塞销径向间隙设计合理数值 | Q8: 子模块分解
M9: 活塞销 | N9: 连杆部件 | O9: 机械力传递：活塞销将爆发压力传递给连杆部件 | P9: 能传递一定的爆发压力，运动副间不发生抱死 | Q9: 子模块分解
M10: 活塞销 | N10: 连杆部件 | O10: 物质交换：连杆部件小头将润滑油传递到活塞销，活塞销将润滑油传递到连杆衬套 | P10: 活塞销和连杆衬套形成运动副，运动副间保证有＞0.023mm厚的油膜厚度 | Q10: 子模块分解
M11: 活塞销 | N11: 连杆部件 | O11: 机械力传递：活塞销将向上的惯性拉力传递给连杆部件 | P11: 1、螺栓能承受一定的拉力 2、连杆体大头在最大的拉力下，变形量＜TBD 3、连杆体小头在最大的拉力下，变形量＜TBD | Q11: 子模块分解
M12: 上连杆轴瓦 | N12: 连杆部件 | O12: 物理连接：过盈配合 | P12: ①上连杆轴瓦与连杆底孔过盈配合，上连杆轴瓦不发生滑移;②连杆部件与上连杆轴瓦定位唇定位 | Q12: 子模块分解
M13: 上连杆轴瓦 | N13: 连杆部件 | O13: 机械力传递：连杆部件将爆发压力传递给上连杆轴瓦 | P13: 连杆部件可将机型最大爆发压力传递给上连杆轴瓦，上连杆轴瓦不发生烧瓦 | Q13: 子模块分解
M14: 下连杆轴瓦 | N14: 连杆部件 | O14: 物理连接：过盈配合 | P14: ①下连杆轴瓦与连杆底孔过盈配合，下连杆轴瓦不发生滑移;②连杆部件与下连杆轴瓦定位唇定位 | Q14: 子模块分解
... M19: 连杆体 | N19: 连杆螺栓 | O19: 机械力传递：连杆体大头承受由惯性作用和离心作用形成的最大拉力，并将其传递至连杆螺栓 | P19: 连杆螺栓能够稳定地连接体干，可承受机型最大的拉力 | Q19: 内部接口

Sheet P图
A1: 步骤三 P图
A2: 噪音
A3: 噪音1：子系统间的变化，零件加工的差异（a、子系统输出偏差对系统的影响；b、接口偏差产生的影响；c、影响一致性的参数，制造装配的影响，识别生产加工的能力，如果能力不足要在图纸上进行补偿补充；d、出现过问题的需要优先）（供应商取水平最低的） 标准需要和生产确认是否符合，不符合按实际生产填写，不满足按过渡标准执行；-需要识别参数对功能的影响 | E3: 噪音2 | F3: 噪音3 | G3: 噪音4 | H3: 噪音5
A4: 个体化差异（生产控制的差异） | E4: 随时间变化（80万公里） | F4: 顾客使用 | G4: 外部环境 | H4: 系统交互作用（其他子系统不利的因素）
A5: 1、影响压缩余隙与压缩比： 连杆部件长度加工公差控制 2、同一台套各缸连杆部件重量偏差控制 3、连杆部件体干硬度偏差控制，同一连杆部件体干硬度偏差控制，屈服强度和抗拉强度需满足一定要求 4、装配工艺控制 5、影响连杆部件质心的一致性： 连杆部件大头胀断面位置要求在以设计面为中面的总宽4mm范围内，连杆体大小头对称度≤0.2 | E5: 1、运动副随时间磨损： 连杆衬套与活塞销的间隙磨损≤1μm/100h | F5: 低档下坡发动机超速 | G5: / | H5: 1、润滑子系统清洁度对连杆部件（衬套表面工作质量）的影响，杂质颗粒度和质量需在一定限值范围内 2、连杆部件衬套/连杆小头需承受活塞销传递的机型最大压力 3、连杆部件大小头需承受活塞销传递的向上的最大惯性作用拉力 4、机油从活塞内冷油道两个出油口流出，经飞溅进入连杆部件小头两侧的进油口：活塞内冷油道两个出油口设计需对着连杆部件小头两侧的进油口
A6: 输入 | C6: 系统或项目 | H6: 预期输出
A7: 工作输入： 1、在缸内最大爆压下，连杆部件将承受最大压力。 2、由于曲柄连杆往复与旋转的惯性作用和离心作用，连杆部件将承受其形成的一定拉力 3、由于曲柄连杆往复与旋转的惯性作用和离心作用，连杆螺栓将承受一定的拉力 | H7: 为满足曲柄连杆模块吸气、压缩、做功、排气冲程，连杆部件可传递发动机运行过程最大压力、和最大拉力，连杆体安全系数满足≥1.2，连杆大头变形量满足要求，连杆螺栓覆盖系数＞2
A8: 功能 | C8: 功能性要求 | D8: 功能性要求 | E8: 控制因素 | G8: 非功能要求 | H8: 非预期输出
A9: 为满足曲柄连杆模块吸气、压缩、做功、排气冲程，连杆部件能稳定可靠的传递压力和承受拉力 | C9: 1、输出扭矩和功率：最大扭矩1500N.m@(1200~1600)r/min；低速扭矩≥1000N.m@800r/min；最大功率257kw/2200(r/min)；2、满足10^7循环次数使用要求。；3在全寿命周期内和额定转速条件下输出扭矩和功率变化量≤0.5%；4、标定点摩擦功≤3.7kw。 | D9: 连杆部件可传递发动机运行最大压力，连杆体安全系数满足≥1.2；在最大拉力下连杆大头变形量满足要求，连杆螺栓覆盖系数≥2 | E9: 主要功能： 1、连杆安全系数满足≥1.2，连杆部件衬套设计面压＜140Mpa，连杆部件衬套选择承压能力＞140Mpa的材料，连杆稳定性分析合格，连杆螺栓覆盖系数≥2，连杆小头变形量≤TBD，连杆大头变形量≤80%连杆轴瓦与轴颈间隙，连杆衬套背压＞10Mpa | G9: 曲柄连杆模块分解给连杆部件的接口需求 1、连杆部件和活塞销接口： 径向间隙TBD（活塞销和连杆部件小头衬套内径设计合理的数值） 2、连杆部件与曲轴的接口： 连杆部件与曲轴轴向间隙TBD：连杆大头宽度和端面外侧直径设计合理的数值 3、连杆部件和整机框架子系统： 连杆部件运动轨迹与曲轴箱（含吸油盆）间距≥5mm： 4、连杆部件和润滑子系统： 连杆部件运动轨迹与机油液面间隙≥5mm 5、连杆部件和缸盖子系统： 活塞与缸盖最小间隙TBD，对应要求曲柄连杆最大轴向（缸套轴向方向）长度设计个里的数值 6、连杆部件和活塞的接口： 连杆部件小头与活塞内腔轴向间隙≥2mm，与活塞内腔顶部≥5mm：连杆体小头宽度18mm，最大厚度7.95mm 7、连杆部件和活塞的接口： 连杆部件小头两侧进油口的设计应能确保活塞内冷油道流出的机油能顺利进入：连杆体小头两侧油孔角度设计需合理（如有） | H9: 1、连杆部件存在重量差，影响曲柄连杆模块扭转振幅：单阶≤0.2deg，合成阶≤0.5deg 2、连杆摆动时，对活塞产生侧向力，活塞对缸套产生侧压力，导致摩擦功增大：TBD
E11: 噪音1： 1、连杆体长度控制公差 2、连杆部件重量控制公差，同一台套各缸连杆部件各缸重量差小于一定值 3、连杆体材料选择70MnVS（C70S6BY）：硬度260HBW~320HBW，同一连杆部件体干硬度差≤35HBW，屈服强度≥550N/mm2，抗拉强度≥950N/mm2 4、连杆螺栓拧紧装配工艺控制 5、连杆部件大头胀断面位置要求在以设计面为中面的总宽4mm范围内，连杆体大小头对称度≤0.2 噪音2： 1、连杆部件衬套硬度控制公差 2、连杆部件衬套内表面粗糙度Ra≤3.2 3、连杆部件衬套参考曲柄连杆开发规范选择是否有油槽以及油槽结构 4、连杆部件衬套参照Q/YC 745.1连杆设计规范，控制圆柱度≤0.006mm 噪音3： 连杆部件大头运动副变形量≤80%连杆轴瓦与轴颈间隙，要求连杆部件体干硬度260HBW~320HBW，同一连杆部件体干硬度差≤35HBW，屈服强度≥550N/mm2，抗拉强度≥950N/mm2 噪音4： 无 噪音5： 1、连杆部件清洁度（含胀断面）控制需满足Q/YC-11标准 2、连杆部件衬套/连杆小头承受活塞销传递的发动机运行最大压力，要求杆身厚度及截面积设计合理数值 3、连杆部件大小头可承受连杆轴瓦传递的曲轴惯性作用和离心作用形成的压力最大，要求大小头设计合理的壁厚
G14: 连杆部件内部接口控制（连杆小头底孔-连杆衬套）： 能传递最大爆压下的压力，并在要求的过盈量（连杆小头底孔直径和连杆衬套外径选择合理的尺寸）下可装配且无相对转动，衬套外表面粗糙度Ra0.8 连杆部件内部接口控制（连杆体-连杆螺栓）： 螺纹配合（连杆螺栓和连杆体螺纹孔需匹配合理），并满足曲轴旋转惯性力向连杆部件传递（1.3倍超速试验） 连杆部件内部接口控制（连杆体内部尺寸）： 连杆螺栓螺纹孔与连杆大头内孔最小距离≥2mm
E16: 非功能要求： 1、活塞销外径控制，连杆部件小头衬套内径控制 2、连杆大头宽度控制，端面外侧直径控制 3、连杆体（连杆螺栓）运动轨迹与曲轴箱（含吸油盆）间距≥5mm 4、连杆体（连杆螺栓）运动轨迹与机油液面间隙≥5mm 5、连杆体长度公差控制 6、连杆体小头宽度和最大厚度控制
E17: 非预期输出： 1、连杆部件存在重量差，影响曲柄连杆模块扭转振幅：单阶≤0.2 deg，合成阶≤0.5deg： 连杆部件重量公差控制，重量按照差异≤10g分组，同一台套各缸连杆部件需为同一组；连杆部件质心需保持一致性（连杆部件大头胀断面位置要求在以设计面为中面的总宽4mm范围内，连杆体对称度≤0.5） 2、连杆摆角时，对活塞产生侧向力，活塞对缸套产生侧压力，导致摩擦功增大 连杆比λ(曲柄半径/连杆长)TBD，连杆长度TBD

Sheet DFMEA
A1: Design Failure Mode and Effects Analysis (Design FMEA) 设计失效模式及影响分析(设计FMEA)
A2: Planning and Preparation (Step 1) 策划与准备 （步骤一）
A3: Company Name: 公司名称: | I3: Product Type: 产品型号: | L3: K08-68 | R3: Subject: 项目: | W3: DFMEA Number: DFMEA 编号: | Y3: DF2209200002-015
A4: Production Location: 生产地址: | I4: PN: 零件号: | L4: A | R4: DFMEA Start Date: DFMEA 开始日期: | W4: DFMEA Revision No: DFMEA 版本号: | Y4: V1.0
A5: Customer Name: 顾客名称: | I5: Model Year / Program(s): 年型/项目: | R5: DFMEA Revision Date: DFMEA 修订日期: | T5: 未发布
A6: Customer PN: 顾客零件号: | I6: Confidentiality Level: 保密级别: | R6: Design Responsibility: 设计责任人: | T6: 韦良锦/结构开发部
A7: Customer Drawing Revision No: 顾客图纸版本号: | I7: Cross-Functional Team: 跨职能团队: | L7: 包毅
A9: Continuous Improvement 持续改善 | C9: Structure Analysis(Setp2) 结构分析（步骤二） | F9: Function Analysis (Step 3) 功能分析 （步骤三） | I9: Failure Analysis (Step 4) 失效分析 （步骤四） | M9: DFMEA Risk Analysis (Step 5) 设计 FMEA 风险分析 （步骤五） | R9: DFMEA Optimization (Step 6) 设计 FMEA 优化（步骤六） | AC9: Remark 备注
A10: Issues 问题# | B10: History/change Authorization (as Applicable) 历史/变更授权(适用时) | C10: 1. Next Higher Level 上一较高级别 | D10: 2. Focus Element 关注要素 | E10: 3. Next Lower Level or Characteristic Type 下一较低级别或特性类 | F10: 1. Next Higher Level Function and Requirement 上一较高级别功能和要求 | G10: 2. Focus Element Function and Requirement 关注要素功能和要求 | H10: 3. Next Lower Level Function and Requirement or Characteristic Type 下一较低级别功能和要求或特性类 | I10: 1. Failure effects(FE) to the Next Higher Level Element and/or End User 对于上一较高级别要素和/或最终用户的失效影响 (FE) | J10: Severity of FE(S) 失效影响的严重度 | K10: 2. Failure Mode(FM) of focus Element 关注要素的失效模式 (FM) | L10: 3. Failure Cause (FC) of the Next Lower Element or Characteristic 下一较低级别要素或特性的失效起因 (FC) | M10: Current Prevention Control(PC) of FC对失效起因的当前预防控制(PC) | N10: Occurrence(O) of FC 失效起因的频度(O) | O10: Current Detection Control(DC) of FC or FM失效起因或失效模式的当前探测控制(DC) | P10: Detection (D) of FC /FM 失效起因/失效模式的探测度 | Q10: DFMEA AP 设计FMEA措施优先级 | R10: DFMEA Preventive Action 预防措施 | S10: DFMEA Detection Action探测措施 | T10: Responsible Person’s Name 负责人姓名 | U10: Target Completion Date 目标完成日期 | V10: Status 状态 | W10: Action Taken with Pointer to Evidence 采取基于证据的措施 | X10: Completion Date 完成日期 | Y10: Severity(S)严重度 | Z10: Occurrence(O)发生度 | AA10: Detection (D) 探测度 | AB10: DFMEA AP措施优先级
C11: 曲柄连杆模块 | D11: 连杆部件 | E11: 连杆体 | F11: 满足结构件可靠性指标要求： 1）曲柄连杆模块结构件：疲劳寿命＞10^7次；强度安全系数≥1.2； 2）曲柄连杆模块清洁度控制：杂质颗粒度和杂质质量控制在一定范围内 | G11: 主要功能：为满足曲柄连杆模块吸气、压缩、做功、排气冲程，连杆部件能稳定可靠的传递压力和承受拉力 要求： 连杆部件可传递发动机运行最大压力，连杆体安全系数满足≥1.2；在最大拉力下连杆大头变形量满足要求，连杆螺栓覆盖系数≥2 | H11: 主要功能：主要功能：为满足曲柄连杆模块吸气、压缩、做功、排气冲程，连杆部件能稳定可靠的传递压力和承受拉力 要求：连接活塞与曲轴，转化往复运动为旋转运动：连杆体材料硬度260HBW~320HBW，同一连杆部件体干硬度差≤35HBW，屈服强度≥550N/mm2，抗拉强度≥950N/mm2，安全系数≥1.2，连杆小头变形量≤TBD，连杆大头变形量≤80%连杆轴瓦与轴颈间隙 | I11: 曲柄连杆模块结构件：疲劳寿命＜10^7次；强度安全系数＜1.2； 2）曲柄连杆模块清洁度控制：杂质颗粒度和杂质质量控制在一定范围内 | J11: 8 | K11: 连杆部件无法传递最大压力，连杆体安全系数满足小于1.2；最大拉力下连杆小头变形量＞TBD，连杆大头变形量＞80%连杆轴瓦与轴颈间隙，连杆螺栓覆盖系数＜2 | L11: 连杆体安全系数小于1.2，连杆体出现弯曲或裂纹 | M11: 参考连杆工程规范选择抗拉能力满足设计要求的材料70MnVS（C70S6BY），硬度260HBW~320HBW，同一连杆部件体干硬度差≤35HBW，屈服强度≥550N/mm2，抗拉强度≥950N/mm2，确保安全系数≥1.2 | N11: 2 | O11: 1-CAE仿真分析 2-连杆疲劳试验 3-整机2000h可靠性试验 | P11: 4 | Q11: L
L12: 连杆体安全系数小于1.2，连杆体出现弯曲或裂纹 | M12: 参考Q/YC 745.1连杆设计规范设计结构（杆身厚度，截面积，大头壁厚、小头壁厚），确保安全系数≥1.2 | N12: 2 | O12: 1-CAE仿真分析 2-连杆疲劳试验 3-整机2000h可靠性试验 | P12: 4 | Q12: L
L13: 连杆小头变形量＞TBD | M13: 参考Q/YC 745.1连杆设计规范设计结构(小头壁厚），连杆小头变形量≤TBD | N13: 2 | O13: 1-CAE仿真分析 2-连杆疲劳试验 3-整机2000h可靠性试验 | P13: 4 | Q13: L
L14: 连杆大头变形量＞80%连杆轴瓦与轴颈间隙 | M14: 参考Q/YC 745.1连杆设计规范设计结构(大头厚度），连杆大头变形量≤80%连杆轴瓦与轴颈间隙 | N14: 2 | O14: 1-CAE仿真分析 2-连杆疲劳试验 3-整机2000h可靠性试验 | P14: 4 | Q14: L
L15: 连杆小头底孔粗糙度低，导致衬套跟转 | M15: 参考Q/YC 745.1连杆设计规范选择粗糙度 | N15: 2 | O15: 整机2000h可靠性试验 | P15: 2 | Q15: L
L16: 连杆小头与连杆衬套过盈量偏大，导致连杆小头烧蚀 | M16: 参考Q/YC 753.1轴瓦设计规范设计过盈量，选择合理的衬套外径，背压＞10Mpa | N16: 2 | O16: 整机2000h可靠性试验 | P16: 2 | Q16: L
E17: 连杆衬套 | H17: 主要功能：为满足曲柄连杆模块吸气、压缩、做功、排气冲程，连杆部件能稳定可靠的传递压力和承受拉力 要求：支持活塞销，贮存机油，减少连杆小头和活塞销之间的摩擦：连杆部件衬套设计面压＜140Mpa | L17: 连杆衬套承压面积小，导致衬套面压过大磨损 | M17: 参考Q/YC 753.1轴瓦设计规范设计面压＜140Mpa | N17: 2 | O17: 整机2000h可靠性试验 | P17: 2 | Q17: L
L18: 连杆衬套所选材料承压能力小，导致衬套面压过大磨损 | M18: 选择承压能力＞140Mpa的材料，硬度（130~180）HBW，内表面粗糙度Ra≤3.2 | N18: 2 | O18: 整机2000h可靠性试验 | P18: 2 | Q18: L
L19: 连杆衬套储油能力偏小，导致衬套干摩擦磨损 | M19: 参考Q/YC 753.1轴瓦设计规范选择人字形结构或者微笑型结构 | N19: 2 | O19: 整机2000h可靠性试验 | P19: 2 | Q19: L
L20: 连杆衬套内孔圆柱度＞0.006mm，导致衬套异常磨损 | M20: 参考Q/YC 745.1连杆设计规范，控制圆柱度≤0.006mm | N20: 2 | O20: 整机2000h可靠性试验 | P20: 3 | Q20: L
L21: 连杆衬套与销过盈量过大或过小，导致衬套烧蚀 | M21: 参考Q/YC 745.1连杆设计规范，配合间隙设计 | N21: 2 | O21: 1-高温拉缸试验 2-整机2000h可靠性试验 | P21: 3 | Q21: L
L22: 连杆衬套厚度偏小，导致衬套烧蚀 | M22: 参考Q/YC 745.1连杆设计规范设计衬套厚度 | N22: 2 | O22: 整机2000h可靠性试验 | P22: 2 | Q22: L
E23: 连杆螺栓 | H23: 主要功能：为满足曲柄连杆模块吸气、压缩、做功、排气冲程，连杆部件能稳定可靠的传递压力和承受拉力 要求：连杆螺栓覆盖系数≥2 | L23: 连杆螺栓抗拉强度偏弱，导致螺栓出现弯曲、断裂现象 | M23: 选择屈服强度＞940Mpa的螺栓材料，最终安全覆盖系数≥2 | N23: 3 | O23: 1-螺栓疲劳试验 2-整机2000h可靠性试验 | P23: 2 | Q23: L
L24: 连杆螺栓力矩过小/过大，导致螺栓出现弯曲、断裂现象 | M24: 拧紧工艺测试：按照要求工艺做拧紧工艺测试，确保螺栓轴力满足规定需求 | N24: 3 | O24: 1-拧紧工艺试验 2、复圆度试验 3-整机2000h可靠性试验 | P24: 4 | Q24: L
E25: 连杆体 | H25: 主要功能：为满足曲柄连杆模块吸气、压缩、做功、排气冲程，连杆部件能稳定可靠的传递压力和承受拉力 要求：连杆部件清洁度（含胀断面）控制需满足Q/YC-11标准 | L25: 连杆部件清洁度（含胀断面）超过Q/YC-11标准，导致轴瓦拉伤抱死 | M25: 图纸按Q/YC 11 清洁度要求执行 | N25: 3 | O25: 整机2000h可靠性试验 | P25: 4 | Q25: L
E26: 连杆衬套 | F26: 非功能要求：曲柄连杆模块分解给连杆部件的接口需求：连杆部件和活塞销接口：间隙TBD（活塞销和连杆部件小头衬套内径设计合理数值） | G26: 非功能要求：曲柄连杆模块分解给连杆部件的接口需求 要求：连杆部件和活塞销间隙TBD | H26: 非功能要求：曲柄连杆模块分解给连杆部件的接口需求 要求：连杆衬套内径设计合理数值 | I26: 曲柄连杆模块接口：连杆部件与活塞销间隙不满足要求 | J26: 8 | K26: 连杆部件与活塞销间隙不满足要求 | L26: 连杆衬套内径不满足规定区间要求 | M26: 参考Q/YC 745.1连杆设计规范：连杆衬套与活塞销间隙 | N26: 2 | O26: 1-整机试装 2-整机2000h可靠性试验 | P26: 3 | Q26: L
E27: 连杆体 | F27: 非功能要求：曲柄连杆模块分解给连杆部件的接口需求：连杆部件与曲轴接口：连杆部件与曲轴轴向间隙设计一定数值，端面外侧直径控制 | G27: 非功能要求：曲柄连杆模块分解给连杆部件的接口需求 要求：连杆部件与曲轴轴向间隙设计一定数值，端面外侧直径控制 | H27: 非功能要求：曲柄连杆模块分解给连杆部件的接口需求 要求：连杆体大头宽度合理设计，端面外侧直径合理设计 | I27: 曲柄连杆模块接口：连杆部件与曲轴间隙偏小，端面外侧直径大于曲轴端面直径，引起连杆大头端面与曲轴异常磨损 | J27: 8 | K27: 连杆部件与曲轴间隙偏小，或端面外侧直径偏小，引起连杆大头端面与曲轴异常磨损 | L27: 连杆体大头宽度偏小，或端面外侧直径偏小 | M27: 参考Q/YC 745.1连杆设计规范设计连杆体与曲轴轴向间隙，连杆大头宽度和端面外侧直径合理设计 | N27: 2 | O27: 整机2000h可靠性试验 | P27: 3 | Q27: L
I28: 曲柄连杆模块接口：连杆部件与曲轴间隙偏大，端面外侧直径大于曲轴端面直径，引起曲柄连杆轴向摆动 | K28: 连杆部件与曲轴间隙偏大，或端面外侧直径偏大，引起连杆大头端面与曲轴异常磨损 | L28: 连杆体大头宽度偏大，或端面外侧直径偏大 | N28: 2 | O28: 整机2000h可靠性试验 | P28: 3 | Q28: L
E29: 连杆体（连杆螺栓） | F29: 非功能要求：曲柄连杆模块分解给连杆部件的接口需求 连杆部件和整机框架子系统： 连杆部件运动轨迹与曲轴箱（含吸油盆）间距≥5mm | G29: 非功能要求：曲柄连杆模块分解给连杆部件的接口需求 要求：连杆部件运动轨迹与曲轴箱（含吸油盆）间距≥5mm | H29: 非功能要求：曲柄连杆模块分解给连杆部件的接口需求 要求：连杆体（连杆螺栓）运动轨迹与曲轴箱（含吸油盆）间距≥5mm | I29: 曲柄连杆模块接口：连杆部件运动轨迹与曲轴箱（含吸油盆）间距＜5mm | J29: 8 | K29: 连杆部件运动轨迹与曲轴箱（含吸油盆）间距＜5mm | L29: 连杆体（连杆螺栓）运动轨迹与曲轴箱（含吸油盆）间距＜5mm | M29: 参考Q/YC 745.1连杆设计规范设计连杆体（连杆螺栓）运动轨迹与曲轴箱（含吸油盆）间距≥5mm | N29: 2 | O29: 整机试装 | P29: 2 | Q29: L
E30: 连杆体（连杆螺栓） | F30: 非功能要求：曲柄连杆模块分解给连杆部件的接口需求 连杆部件和润滑子系统： 连杆部件运动轨迹与机油液面间隙≥5mm | G30: 非功能要求：曲柄连杆模块分解给连杆部件的接口需求 要求：连杆部件运动轨迹与机油液面间隙≥5mm | H30: 非功能要求：曲柄连杆模块分解给连杆部件的接口需求 要求：连杆体（连杆螺栓）运动轨迹与机油液面间隙≥5mm | I30: 曲柄连杆模块接口：连杆部件运动轨迹与机油液面间隙＜5mm | J30: 6 | K30: 连杆部件运动轨迹与机油液面间隙＜5mm | L30: 连杆体（连杆螺栓）运动轨迹与机油液面间隙＜5mm | M30: 参考Q/YC 745.1连杆设计规范设计连杆体（连杆螺栓）运动轨迹与机油液面间隙≥5mm | N30: 2 | O30: 曲轴箱通风试验 | P30: 2 | Q30: L
E31: 连杆体 | F31: 非功能要求：曲柄连杆模块分解给连杆部件的接口需求： 曲柄连杆模块和缸盖子系统： 活塞与缸盖最小间隙TBD，对应曲柄连杆最大轴向（缸套轴向方向）长度TBD 要求：连杆长度公差控制 | G31: 非功能要求：曲柄连杆模块分解给连杆部件的接口需求 要求：连杆部件长度公差控制 | H31: 非功能要求：曲柄连杆模块分解给连杆部件的接口需求 要求：连杆体长度公差控制 | I31: 曲柄连杆最大轴向（缸套轴向方向）长度超过要求范围 | J31: 8 | K31: 连杆长度偏大或偏小 | L31: 连杆长度偏大或偏小 | M31: 尺寸链校核 | N31: 3 | O31: 1-压缩余隙测试 2-气门运动规律试验 | P31: 2 | Q31: L
E32: 连杆体 | F32: 非功能要求：曲柄连杆模块分解给连杆部件的接口需求： 连杆部件与活塞的接口： 连杆部件小头与活塞内腔轴向间隙≥2mm，与活塞内腔顶部≥5mm | G32: 非功能要求：曲柄连杆模块分解给连杆部件的接口需求 要求：连杆部件小头与活塞内腔轴向间隙≥2mm，与活塞内腔顶部≥5mm | H32: 非功能要求：曲柄连杆模块分解给连杆部件的接口需求 要求：连杆体小头宽度18mm，最大厚度7.95mm | I32: 曲柄连杆模块连杆部件小头与活塞内腔轴向间隙＜2mm，与活塞内腔顶部＜5mm | J32: 8 | K32: 连杆部件小头与活塞内腔轴向间隙≥2mm，与活塞内腔顶部≥5mm | L32: 连杆体小头宽大＞18mm，最大厚度＞7.95mm | M32: 参考Q/YC 745.1连杆设计规范：设计连杆体小头与活塞内腔轴向间隙≥2mm，与活塞内腔顶部≥5mm（连杆体小头宽度18mm，最大厚度7.95mm） | N32: 2 | O32: 整机试装 | P32: 2 | Q32: L
E33: 连杆体 | F33: 非功能要求：曲柄连杆模块分解给连杆部件的接口需求： 连杆部件与曲轴的接口： 连杆部件小头两侧进油口的设计应能确保活塞内冷油道流出的机油能顺利进入 | G33: 非功能要求：曲柄连杆模块分解给连杆部件的接口需求 要求：连杆部件小头两侧进油口的设计应能确保活塞内冷油道流出的机油能顺利进入 | H33: 非功能要求：曲柄连杆模块分解给连杆部件的接口需求 要求：连杆体小头两侧油孔角度合理设计 | I33: 曲柄连杆模块连杆部件小头两侧进油口的设计未能让活塞内冷油道流出的机油能进入 | J33: 8 | K33: 连杆部件小头两侧进油口的设计未能让活塞内冷油道流出的机油能进入 | L33: 连杆体小头两侧油孔角度偏大或偏小 | M33: 参考Q/YC 745.1连杆设计规范：设计连杆部件小头两侧进油口确保对着活塞出油口（连杆体小头两侧油孔角度 | N33: 2 | O33: 整机2000h可靠性试验 | P33: 4 | Q33: L
E34: 连杆体 | F34: 非预期输出： 1、曲柄连杆模块扭转振幅：单阶≤0.2 deg，合成阶≤0.5deg；（连杆部件不同发动机重量差异≤100g，同一台套差异≤10g） 2、曲柄连杆模块摩擦功在标定点≤TBD | G34: 非预期输出： 1、曲柄连杆模块扭转振幅：单阶≤0.2 deg，合成阶≤0.5deg； 2、曲柄连杆模块摩擦功在标定点≤TBD 要求：连杆部件重量设计合理公差，重量按照差异≤10g分组，同一台套各缸连杆部件需为同一组 | H34: 非预期输出： 1、曲柄连杆模块扭转振幅：单阶≤0.2 deg，合成阶≤0.5deg； 2、曲柄连杆模块摩擦功在标定点≤TBD 要求：连杆体重量TBD，重量差异≤10g | I34: 曲柄连杆模块扭转振幅：单阶＞0.2 deg，合成阶＞0.5deg； | J34: 5 | K34: 连杆部件重量超出公差范围，同一台套重量差异＞10g | L34: 连杆体重量差异超出公差范围，导致连杆部件不同发动机重量差异＞100g，同一台套差异＞10g | M34: 图纸设计参考K08一代，实物样件按照重量大小分组 | N34: 4 | O34: NVH测试 | P34: 2 | Q34: L
G35: 非预期输出： 1、曲柄连杆模块扭转振幅：单阶≤0.2 deg，合成阶≤0.5deg； 2、曲柄连杆模块摩擦功在标定点≤TBD 要求：连杆部件质心需保持一致性（连杆部件大头胀断面位置要求在以设计面为中面的总宽4mm范围内，连杆体大小头对称度≤0.2） | H35: 非预期输出： 1、曲柄连杆模块扭转振幅：单阶≤0.2 deg，合成阶≤0.5deg； 2、曲柄连杆模块摩擦功在标定点≤TBD 要求：连杆部件大头胀断面位置要求在以设计面为中面的总宽4mm范围内，连杆体大小头对称度≤0.2 | I35: 曲柄连杆模块扭转振幅：单阶＞0.2 deg，合成阶＞0.5deg； | J35: 5 | K35: 连杆部件质心一致性差 | L35: 连杆部件大头胀断面位置超过在以设计面为中面的总宽4mm范围内，连杆体大小头对称度＞0.2 | M35: 图纸设计参考K08一代，设计连杆部件大头胀断面位置在以设计面为中面的总宽4mm范围内，连杆体大小头对称度≤0.2 | N35: 4 | O35: NVH测试 | P35: 2 | Q35: L
G36: 非预期输出： 1、曲柄连杆模块扭转振幅：单阶≤0.2 deg，合成阶≤0.5deg； 2、曲柄连杆模块摩擦功在标定点≤TBD 要求：连杆部件摆角时，对活塞产生侧向力，活塞对缸套产生侧向力，导致摩擦功增大 | H36: 非预期输出： 1、曲柄连杆模块扭转振幅：单阶≤0.2 deg，合成阶≤0.5deg； 2、曲柄连杆模块摩擦功在标定点≤TBD 要求：连杆比λ（曲柄半径/连杆长）设计合理 | I36: 曲柄连杆模块摩擦功在标定点＞TBD | J36: 5 | K36: 连杆部件摆角过大，使活塞对缸套的侧向力过大，导致摩擦功增大 | L36: 连杆比λ（曲柄半径/连杆长）偏大 | M36: 1、参考Q/YC 745.1连杆设计规范设计连杆比λ(曲柄半径/连杆长) 2、CAE分析 | N36: 2 | O36: 摩擦功测试 | P36: 2 | Q36: L

Sheet 严重度S
B2: 产品一般评估严重度（S）
B3: 根据以下标准对潜在失效影响进行评级
B4: S | C4: 影响 | D4: 严重度标准
B5: 10 | C5: 非常高 | D5: 影响到车辆和/或其它车辆的操作安全，驾驶员、乘客、道路使用者或行人的健康状况。
B6: 9 | D6: 不符合法规。
B7: 8 | C7: 高 | D7: 在预期使用寿命内，失去正常驾驶所必需的车辆主要功能。
B8: 7 | D8: 在预期使用寿命内，降低正常驾驶所必需的车辆主要功能。
B9: 6 | C9: 中 | D9: 失去车辆的次要功能
B10: 5 | D10: 降低车辆的次要功能
B11: 4 | D11: 外观、声音、振动、粗糙度或触感令人感觉非常不舒服。
B12: 3 | C12: 低 | D12: 外观、声音、振动、粗糙度或触感令人感觉中度不舒服。
B13: 2 | D13: 外观、声音、振动、粗糙度或触感令人略微感觉不舒服。
B14: 1 | C14: 非常低 | D14: 没有觉察的影响。

Sheet 频度O
B2: 产品的潜在频度（O） | E2: 公司或产品线示例
B3: O | C3: 对失效起因发生的预测 | D3: 频度标准.DFMEA
B4: 10 | C4: 极高 | D4: 在无操作经验和/或在运行条件不可控制的情况下的任何地方对新技术的首次应用。没有对产品进行验证和/或确认的经验。不存在标准，且尚未确定最佳实践。 | E4: 完全创新
D5: 预防控制不能预测使用现场绩效或不存在预防控制。
B6: 9 | C6: 非常高 | D6: 在公司内首次应用具有技术创新或材料的设计。新应用，或工作周期/运行条件有改变。没有对产品进行验证和/或确认的经验。 | E6: 市场有，公司第一次，无验证经验，预防不行
D7: 预防控制不是针对确定特定要求的性能。
B8: 8 | D8: 在新应用内首次使用具备创新技术的设计产品或材料。新应用，或工作周期/运行条件有改变。没有对产品进行验证和/或确认的经验。 | E8: 市场有，公司第一次，无验证经验，预防不可靠
D9: 极少存在现有标准和最佳实践，不能直接用于该设计产品。预防控制不能可靠地反映使用现场绩效。
B10: 7 | C10: 高 | D10: 根据相似技术和材料的新型设计。新应用，或工作周期/运行条件有改变，没有对产品进行验证和/确认的经验。 | E10: 相似应用，环境变，无验证，有类似成功案例
D11: 标准、最佳实践和设计规则符合基础设计要求，但不适用于创新产品。预防控制提供了有限的性能指标。
B12: 6 | D12: 应用现有技术和材料，与之前设计相似。类似应用，工作周期或运行条件有改变。之前的测试或使用现场经验。 | E12: 类似设计，环境变，有验证，有实施套路，预防有点用
D13: 存在标准和设计规则，但不足以确保不会出现失效起因。预防控制提供了预防失效起因的部分能力。
B14: 5 | C14: 中 | D14: 应用成熟技术和材料，与之前设计相比有细节上的变化。类似的应用、工作周期或运行条件。之前的测试或使用现场经验，或为具有与失效相关测试经验的新设计。 | E14: 应用不变，环境改，有验证，有经验，预防有相关性
D15: 在之前设计中所学到的与解决设计问题相关的教训。在本设计中对最佳实践进行再评估，但尚未经过验证。预防控制能够发现与失效起因相关的产品缺陷，并提供部分性能指标。
B16: 4 | D16: 与短期现场使用暴露几乎相同的设计。类似应用，工作周期或运行条件有细微变化。之前测试或使用现场经验。之前设计和为新设计而进行的改变符合最佳实践、标准和规范要求。 | E16: 应用不变，环境小改，有验证，预防有用
D17: 预防控制能够发现与失效起因相关的产品缺陷，很可能地反映设计符合性。
B18: 3 | C18: 低 | D18: 对已知设计（相同应用，在工作周期或操作条件方面）和测试或类似运行条件下的现场经验的细微变化或成功完成测试程序的新设计。 | E18: 抄最佳实践
D19: 考虑到之前设计的经验教训，设计预计符合标准和最佳实践。预防控制能够发现与失效起因相关的产品缺陷，并预测了与生产设计的一致性。
B20: 2 | C20: 非常低 | D20: 与长期现场暴露几乎相同的设计。相同应用，具备类似的工作周期或运行条件。在类似运行条件下的测试或使用现场经验。 | E20: 抄最佳实践，完全不改
D21: 考虑到之前设计的经验教训并对其具备充足的信心，设计预计符合标准和最佳实践。预防控制能够发现与失效起因相关的产品缺陷，并显示出对设计符合性的信心。
B22: 1 | C22: 极低 | D22: 失效通过预防措施控制消除，通过设计失效起因不可能发生。 | E22: 设计防错
B23: 产品经验：在公司内使用产品的历史（新品设计、应用或使用案例）。已经完成的探测控制结果提供了设计经验。
B24: 预防控制：在产品设计中使用最佳实践、设计规则、公司标准、经验教训、行业标准、材料规范、政府规定、以及预防为导向的分析工具的有效性（分析工具包括计算机辅助工程、数学建模、模拟研究、公差叠加和设计案例边际）。
B25: 注：频度10、9、8、7可根据产品验证活动降低。

Sheet 探测度D
B2: 产品设计验证的潜在探测度（D）
B3: 根据探测方法成熟度和探测机会对探测控制进行评级。
B4: D | C4: 探测能力 | D4: 探测标准 | E4: 探测机会
B5: 10 | C5: 非常低 | D5: 尚未制定测试过程。 | E5: 尚未确定测试方法
B6: 9 | D6: 没有为探测失效模式或失效起因而特别地设计测试方法。 | E6: 通过/不通过测试、失效测试、老化测试
B7: 8 | C7: 低 | D7: 新测试方法，尚未经过验证 | E7: 通过/不通过测试、失效测试、老化测试
B8: 7 | D8: 已经验证的测试方法，该方法用于功能性验证或性能、质量、可靠性以及耐久性确认；测试计划时间在产品开发周期内较迟，如果测试失败将导致重新设计、重新开模具导致生产延迟。 | E8: 通过/不通过测试
B9: 6 | C9: 中 | E9: 失效测试
B10: 5 | E10: 老化测试
B11: 4 | C11: 高 | D11: 已经验证的测试方法，该方法用于功能性验证或性能、质量、可靠性以及耐久性确认；计划时间充分，可以在开始生产之前修改生产工装。 | E11: 通过/不通过测试
B12: 3 | E12: 失效测试
B13: 2 | E13: 老化测试
B14: 1 | C14: 非常高 | D14: 之前测试证明不会出现失效模式或失效起因，或者探测方法经过实践验证总是能够探测到失效模式或失效起因。
B17: 通过/不通过=ok/ not ok，某项试验通不通过，如可靠性验证通过/不通过；失效=验证直到零件出现失效；老化=通过多次累计试验，得出规律，如威布尔分布 打5~7或2~4的依据→评估是否会影响APQP
